Workbook

Sheet RAW_Data
A1: ID | B1: Employee_Name | C1: TxID | D1: TxID_no | E1: Status | F1: Hired_Date | G1: Agency_HiredDate | H1: Job_Title | I1: Office_Location | J1: Language | K1: ERC_Level | L1: Email_TELUS | M1: Supervisor | N1: Operations_Manager | O1: Phone_No_1 | P1: Phone_No_2 | Q1: Phone_No_3 | R1: Old_MAS_Initials | S1: MAS_Initials | T1: Laptop Asset # | U1: MAS_EmployeeID | V1: Apps_MAS_Username | W1: Email_TELUS_International | X1: Apps_AvayaOneX_Extension | Y1: Avaya_AgentLoginID | Z1: Apps_AvayaCMS_Username | AA1: Apps_SAFE_Username | AB1: Apps_IMMIX_Username | AC1: Apps_Manitou_Userename | AD1: Skills | AE1: First_Aid_ExpiringDate | AF1: TMA_Level1_Date | AG1: TMA_Level1_CertificateNo | AH1: TMA_Level2_Date | AI1: TMA_Level2_CertificateNo | AJ1: FTE | AK1: Pay_Group | AL1: Schedule_Type | AM1: Schedule_Start_Time | AN1: Schedule_EndTime | AO1: Phone_No_Int1 | AP1: Phone_No_Int2 | AQ1: Name_First | AR1: Name_Last | AS1: Emergency_Contact_1_Name | AT1: Emergency_Contact_1_Phone | AU1: Emergency_Contact_1_Relationship | AV1: Emergency_Contact_2_Name | AW1: Emergency_Contact_2_Phone | AX1: Emergency_Contact_2_Relationship | AY1: Employee_Name_Proper | AZ1: First _Aid_ CertificateNo | BA1: Lenel_ERC_PIN | BB1: Sch_DaySUN | BC1: Sch_DayMON | BD1: Sch_DayTUE | BE1: Sch_DayWED | BF1: Sch_DayTHU | BG1: Sch_DayFRI | BH1: Sch_DaySAT | BI1: Schedule _Comment | BJ1: Schedule_Shift | BK1: Apps_CiscoIP_Extension | BL1: Level 2 Training Date | BM1: Level 2 Exam Date | BN1: Level 2 Salary Adjustment completed | BO1: Level 3 Training Date | BP1: Level 3 Exam Date | BQ1: Level 3 Salary Adjustment completed | BR1: Level 4 Training Date | BS1: Level 4 Exam Date | BT1: Level 4 Salary Adjustment completed | BU1: Unionized | BV1: AHA Status | BW1: Contracted Hrs | BX1: FTE Status | BY1: Level 1 Exam Date | BZ1: Item Type | CA1: Path
A2: 612 | B2: Abouda, Mohammed | C2: T773560 | D2: 773560 | E2: Active | F2: 45957 | H2: Monitoring Specialist II (Regular) | I2: Ottawa | J2: Bilingual-French | K2: 2 | L2: mo.abouda@telus.com | M2: Lo, Mamadou | N2: Pandza, Vinko | O2: 4383659110 | S2: M0511 | T2: PF3QMD9C | U2: 100773560 | X2: 15141294009 | Y2: 1060061 | AJ2: 1.00 - (34 - 37.5 Hours) | AK2: Operator | AL2: Week B (7/7) | AM2: 0.27083333 | AN2: 0.70833333 | AQ2: Mohammed | AR2: Abouda | AY2: Mohammed Abouda | BA2: Pending/Required | BB2: x | BC2: x | BD2: x | BE2: x | BF2: x | BG2: x | BH2: x | BJ2: Morning (from 05h00 - 10h30) | BL2: 46056 | BM2: 46092 | BU2: No | BV2: Mobile | BX2: Full Time | BY2: 46030 | BZ2: Item | CA2: sites/SAM/Restricted_HUB/Lists/MEL
A3: 38 | B3: Adrien, Goddard | C3: T955706 | D3: 955706 | E3: Active | F3: 43171 | H3: Monitoring Specialist II (Senior) | I3: Montreal | J3: Bilingual-French | K3: 4 | L3: adrien.goddard@telus.com | M3: Lo, Mamadou | N3: Pandza, Vinko | O3: 514-796-7601 | R3: MA4G | S3: M0062 | T3: L112611 | U3: 100955706 | V3: adriengoddard | X3: 15143732207 | Y3: 1066843 | AD3: Video Monitoring;#5;#Video Verification;#4;#Question Line;#6;#Complaint Line;#7;#Data Entry Advanced;#8 | AF3: 43336 | AG3: 26564 | AJ3: 1.00 - (34 - 37.5 Hours) | AK3: Operator | AL3: 46115 | AM3: 0.125 | AN3: 0.5 | AQ3: Goddard | AR3: Adrien | AY3: Goddard Adrien | BA3: 66843 | BB3: _ | BC3: _ | BD3: x | BE3: x | BF3: x | BG3: _ | BH3: x | BI3: Travaille le Samedi 05:00 - 14:00 | BJ3: Morning (from 05h00 - 10h30) | BL3: 43262 | BM3: 43314 | BN3: Yes | BO3: 45236 | BP3: 45236 | BQ3: Yes | BR3: 44873 | BS3: 45041 | BT3: Yes | BU3: No | BV3: Virtual | BW3: 34 | BX3: Full Time | BY3: 43243 | BZ3: Item | CA3: sites/SAM/Restricted_HUB/Lists/MEL
A4: 39 | B4: Aidoud, Nabil | C4: T955715 | D4: 955715 | E4: Active | F4: 43744 | G4: 43437 | H4: Monitoring Specialist II (Senior) | I4: Ottawa | J4: Bilingual-French | K4: 4 | L4: nabil.aidoud@telus.com | M4: Dhindsa, Sukhjinder | N4: Khara, Tanu | O4: 819-437-1740 | R4: ON4A | S4: M0064 | T4: L112422 | U4: 100955715 | V4: naidoud | X4: 16131293063 | Y4: 1062011 | AA4: Agent | AD4: SmartWear;#3;#Basic Troubleshooting;#2;#Complaint Line;#7;#Question Line;#6;#Video Monitoring;#5 | AF4: 43570 | AG4: 28153 | AJ4: 1.00 - (34 - 37.5 Hours) | AK4: Operator | AL4: Week B (7/7) | AM4: 0.35416667 | AN4: 0.77083333 | AQ4: Nabil | AR4: Aidoud | AY4: Nabil Aidoud | BA4: Pending/Required | BB4: x | BC4: x | BD4: x | BE4: x | BF4: x | BG4: x | BH4: x | BJ4: Morning (from 05h00 - 10h30) | BL4: 43526 | BM4: 43556 | BN4: Yes | BO4: 45245 | BP4: 45443 | BQ4: Yes | BR4: 45881 | BS4: 45954 | BT4: Yes | BU4: No | BV4: Virtual | BW4: 35 | BX4: Full Time | BY4: 43497 | BZ4: Item | CA4: sites/SAM/Restricted_HUB/Lists/MEL
A5: 409 | B5: Akherraz, Hajar | C5: T996872 | D5: 996872 | E5: Active | F5: 44970 | H5: Monitoring Specialist II (Senior) | I5: Remote Area | J5: French | K5: 4 | L5: hajar.akharraz@telus.com | M5: Herrati, Houcine | N5: Khara, Tanu | O5: 5145010683 | R5: MRh1A | S5: M0065 | T5: L804958 | U5: 100996872 | V5: T996872 | X5: 19051291051 | Y5: 1110197 | AD5: Complaint Line;#7;#Question Line;#6;#Video Monitoring;#5 | AF5: 45546 | AG5: 996872 | AJ5: 1.00 - (34 - 37.5 Hours) | AK5: Operator | AL5: 46115 | AM5: 0.89583333 | AN5: 0.27083333 | AQ5: Hajar | AR5: Akherraz | AY5: Hajar Akherraz | BA5: Issued | BB5: x | BC5: x | BD5: _ | BE5: _ | BF5: x | BG5: x | BH5: _ | BJ5: Night (from 18h30 - 01h00) | BL5: 45070 | BM5: 45127 | BN5: Yes | BO5: 45923 | BP5: 45979 | BQ5: Yes | BR5: 46064 | BS5: 46121 | BT5: Yes | BU5: No | BV5: Virtual | BW5: 34 | BX5: Full Time | BY5: 45040 | BZ5: Item | CA5: sites/SAM/Restricted_HUB/Lists/MEL
A6: 382 | B6: Aquilario, Lester | C6: T988376 | D6: 988376 | E6: Active | F6: 44438 | H6: Monitoring Specialist II (Senior) | I6: Burnaby | J6: English | K6: 3 | L6: LESTER.AQUILARIO@TELUS.COM | M6: Dhindsa, Sukhjinder | N6: Khara, Tanu | O6: 6048284259 | S6: M0024 | T6: L805964 | U6: 100988376 | V6: T988376 | X6: 16041295008 | Y6: 1030029 | AC6: lester | AD6: SmartWear;#3;#Basic Troubleshooting;#2;#Question Line;#6;#Complaint Line;#7 | AF6: 45736 | AJ6: 1.00 - (34 - 37.5 Hours) | AK6: Operator | AL6: 46115 | AM6: 0.4375 | AN6: 0.8125 | AQ6: Lester | AR6: Aquilario | AY6: Lester Aquilario | BA6: Pending/Required | BB6: _ | BC6: _ | BD6: x | BE6: x | BF6: x | BG6: _ | BH6: x | BJ6: Morning (from 05h00 - 10h30) | BO6: 46093 | BU6: No | BV6: Mobile | BW6: 34 | BX6: Full Time | BZ6: Item | CA6: sites/SAM/Restricted_HUB/Lists/MEL
A7: 393 | B7: Audet, Dominic | C7: T996384 | D7: 996384 | E7: Active | F7: 44942 | H7: Monitoring Specialist II (Senior) | I7: Montreal | J7: French | K7: 4 | L7: dominic.audet@telus.com | M7: Diegue, Kerry | N7: Pandza, Vinko | O7: 4388299413 | S7: M0068 | T7: L111318 | U7: 100996384 | V7: T996384 | X7: 15141294047 | Y7: 1060018 | AD7: Basic Troubleshooting;#2;#Complaint Line;#7;#Question Line;#6;#Video Monitoring;#5;#Video Verification;#4;#Video Monitoring Arpel only;#10 | AF7: 45546 | AG7: 996384 | AJ7: 1.00 - (34 - 37.5 Hours) | AK7: Operator | AL7: 46115 | AM7: 0.72916667 | AN7: 0.083333333 | AQ7: Dominic | AR7: Audet | AS7: Sylvain Audet appelé 2x de suite (Père) | AT7: 438-931-5390 | AY7: Dominic Audet | BA7: 60053 | BB7: _ | BC7: x | BD7: x | BE7: x | BF7: _ | BG7: _ | BH7: x | BJ7: Evening (from 10h45 - 17h00) | BL7: 45972 | BM7: 45972 | BN7: Yes | BO7: 45921 | BP7: 45972 | BQ7: Yes | BR7: 46056 | BS7: 46097 | BT7: No | BU7: No | BV7: Mobile | BW7: 34 | BX7: Full Time | BY7: 45033 | BZ7: Item | CA7: sites/SAM/Restricted_HUB/Lists/MEL
A8: 52 | B8: Auger, Adrien | C8: T973054 | D8: 973054 | E8: Active | F8: 42605 | H8: Monitoring Specialist II (Senior) | I8: Victoria | J8: English | K8: 4 | L8: adrien.auger@telus.com | M8: Rwano, Guy Fremin | N8: Pandza, Vinko | O8: 2502173997 | R8: MIA1A | S8: M0069 | T8: L805746 | U8: 100973054 | V8: t973054 | X8: 16041295068 | Y8: 1030139 | AA8: Agent | AC8: ADRIENA | AD8: SmartWear;#3;#Question Line;#6;#Complaint Line;#7;#Basic Troubleshooting;#2;#Data Entry Advanced;#8;#Video Monitoring;#5;#Video Verification;#4 | AF8: 45090 | AJ8: 1.00 - (34 - 37.5 Hours) | AK8: Operator | AL8: Week A (7/7) | AM8: 0.73958333 | AN8: 0.17708333 | AQ8: Adrien | AR8: Auger | AY8: Adrien Auger | BB8: x | BC8: x | BD8: x | BE8: x | BF8: x | BG8: x | BH8: x | BJ8: Night (from 18h30 - 01h00) | BL8: 44718 | BM8: 44718 | BN8: Yes | BO8: 45275 | BP8: 45408 | BQ8: Yes | BR8: 45769 | BS8: 45819 | BU8: No | BV8: Mobile | BW8: 35 | BX8: Full Time | BY8: 42605 | BZ8: Item | CA8: sites/SAM/Restricted_HUB/Lists/MEL
A9: 54 | B9: Austin, Stephanie | C9: T983229 | D9: 983229 | E9: Long Term Disability | F9: 44648 | H9: Monitoring Specialist II (Regular) | I9: Remote Area | J9: Bilingual-English | K9: 2 | L9: stephanie.austin@telus.com | M9: Coghiel, Caren | N9: Khara, Tanu | O9: 5063991686 | R9: MMS1A | S9: M0070 | T9: L116750 | U9: 100983229 | V9: t983229 | X9: 15141294065 | Y9: 1066108 | AF9: 45182 | AG9: 968432 | AJ9: 1.00 - (34 - 37.5 Hours) | AK9: Operator | AL9: Week B (7/7) | AM9: 0.58333333 | AN9: 0.020833333 | AQ9: Stephanie | AR9: Austin | AY9: Stephanie Austin | BB9: x | BC9: x | BD9: x | BE9: x | BF9: x | BG9: x | BH9: x | BI9: Agent work with Atlantic time zone (+1 hour from EST) | BJ9: Evening (from 10h45 - 17h00) | BL9: 44768 | BM9: 45138 | BN9: Yes | BU9: No | BV9: Virtual | BW9: 35 | BX9: Full Time | BY9: 44760 | BZ9: Item | CA9: sites/SAM/Restricted_HUB/Lists/MEL
A10: 617 | B10: Baisi , Jean-Gabriel | C10: T773726 | D10: 773726 | E10: Active | F10: 45957 | H10: Monitoring Specialist II (Regular) | I10: Ottawa | J10: Bilingual-French | K10: 2 | L10: john.baisi@telus.com | M10: Rwano, Guy Fremin | N10: Pandza, Vinko | O10: 6133159045 | S10: M0516 | T10: PF3PX117 | U10: 100773726 | X10: 15141294014 | Y10: 1060067 | AJ10: 1.00 - (34 - 37.5 Hours) | AK10: Operator | AL10: Week A (7/7) | AM10: 0.375 | AN10: 0.8125 | AQ10: Jean-Gabriel | AR10: Baisi | AY10: Jean-Gabriel Baisi | BA10: Pending/Required | BB10: x | BC10: x | BD10: x | BE10: x | BF10: x | BG10: x | BH10: x | BJ10: Morning (from 05h00 - 10h30) | BL10: 46049 | BM10: 46095 | BN10: Yes | BX10: Full Time | BY10: 46025 | BZ10: Item | CA10: sites/SAM/Restricted_HUB/Lists/MEL
A11: 66 | B11: Beaulieu, Angelyk | C11: T956508 | D11: 956508 | E11: Maternity/Paternity Leave | F11: 43948 | H11: Monitoring Specialist II (Senior) | I11: Montreal | J11: Bilingual-French | K11: 4 | L11: angelyk.beaulieu@telus.com | M11: Herrati, Houcine | N11: Khara, Tanu | O11: 2638813298 | R11: MA0B | S11: M0072 | T11: L112640 | U11: 100956508 | V11: angelykbeaulieu | X11: 15141294248 | Y11: 1067279 | AD11: Basic Troubleshooting;#2;#Complaint Line;#7;#Question Line;#6;#Video Monitoring;#5 | AF11: 44617 | AG11: 33018 | AH11: 45707 | AI11: 33018 | AJ11: 1.00 - (34 - 37.5 Hours) | AK11: Operator | AL11: Week A (7/7) | AM11: 0.8125 | AN11: 0.22916667 | AQ11: Angelyk | AR11: Beaulieu | AY11: Angelyk Beaulieu | BA11: 66150 | BB11: x | BC11: x | BD11: x | BE11: x | BF11: x | BG11: x | BH11: x | BJ11: Night (from 18h30 - 01h00) | BL11: 44055 | BM11: 44105 | BN11: Yes | BO11: 45236 | BP11: 45613 | BQ11: Yes | BR11: 44873 | BS11: 45041 | BT11: Yes | BU11: No | BV11: Mobile | BW11: 37.5 | BX11: Full Time | BY11: 44035 | BZ11: Item | CA11: sites/SAM/Restricted_HUB/Lists/MEL
A12: 69 | B12: Bercier, France | C12: T956514 | D12: 956514 | E12: Active | F12: 42878 | H12: Monitoring Specialist II (Senior) | I12: Ottawa | J12: Bilingual-French | K12: 4 | L12: france.bercier@telus.com | M12: Rwano, Guy Fremin | N12: Pandza, Vinko | O12: 819-968-1181 | R12: OF1B | S12: M0075 | T12: L112632 | U12: 100956514 | V12: fbercier | X12: 16131293079 | Y12: 1062436 | AD12: Complaint Line;#7;#Question Line;#6;#SME;#11;#SmartWear;#3;#Video Monitoring;#5;#Video Verification;#4 | AF12: 45539 | AG12: 956514 | AJ12: 1.00 - (34 - 37.5 Hours) | AK12: Operator | AL12: Week A (7/7) | AM12: 0.33333333 | AN12: 0.75 | AQ12: France | AR12: Bercier | AY12: France Bercier | BB12: x | BC12: x | BD12: x | BE12: x | BF12: x | BG12: x | BH12: x | BJ12: Morning (from 05h00 - 10h30) | BL12: 42878 | BM12: 42910 | BN12: Yes | BO12: 43046 | BP12: 43088 | BQ12: Yes | BR12: 46063 | BS12: 46115 | BU12: No | BV12: Virtual | BW12: 35 | BX12: Full Time | BY12: 42910 | BZ12: Item | CA12: sites/SAM/Restricted_HUB/Lists/MEL
A13: 641 | B13: Bindhu Harikrishnan | C13: T6001665 | D13: 6001665 | E13: Active | F13: 46146 | H13: Monitoring Specialist I (Junior) | I13: Calgary | J13: English | K13: Trainee | L13: bindhu.harikrishnan@telus.com | M13: Diegue, Kerry | N13: Pandza, Vinko | O13: 3688868549 | T13: SD00RVYH | X13: 15141294043 | Y13: 1060069 | AJ13: 1.00 - (34 - 37.5 Hours) | AK13: Specialist - Hourly | AQ13: Bindhu | AR13: Harikrishnan | AY13: Bindhu Harikrishnan | BA13: Pending/Required | BB13: _ | BC13: _ | BD13: _ | BE13: _ | BF13: _ | BU13: Yes | BV13: Virtual | BW13: 35 | BX13: Full Time | BZ13: Item | CA13: sites/SAM/Restricted_HUB/Lists/MEL
A14: 75 | B14: Bonnet, Cassandra | C14: T956369 | D14: 956369 | E14: Maternity/Paternity Leave | F14: 42932 | G14: 42824 | H14: Monitoring Specialist II (Senior) | I14: Montreal | J14: Bilingual-English | K14: 4 | L14: cassandra.bonnet@telus.com | M14: Kollias, Peter | N14: Pandza, Vinko | O14: 514-568-5992 | R14: MC3B | S14: M0078 | T14: L112597 | U14: 100956369 | V14: cbonnet | X14: 15141294147 | Y14: 1066711 | AA14: Agent | AD14: Complaint Line;#7;#Data Entry Advanced;#8;#Question Line;#6;#SmartWear;#3;#Basic Troubleshooting;#2;#Video Monitoring;#5;#Video Verification;#4 | AF14: 43067 | AG14: 24782 | AJ14: 1.00 - (34 - 37.5 Hours) | AK14: Operator | AL14: Week A (7/7) | AM14: 0.33333333 | AN14: 0.75 | AQ14: Cassandra | AR14: Bonnet | AY14: Cassandra Bonnet | BA14: 66649 | BB14: x | BC14: x | BD14: x | BE14: x | BF14: x | BG14: x | BH14: x | BJ14: Morning (from 05h00 - 10h30) | BL14: 43217 | BM14: 43217 | BN14: Yes | BO14: 43217 | BP14: 43582 | BQ14: Yes | BT14: Yes | BU14: No | BV14: Mobile | BW14: 35 | BX14: Full Time | BY14: 42852 | BZ14: Item | CA14: sites/SAM/Restricted_HUB/Lists/MEL
A15: 77 | B15: Borromeo, Ronadell | C15: T956358 | D15: 956358 | E15: Short Term Disability | F15: 41953 | H15: Monitoring Specialist II (Regular) | I15: Montreal | J15: English | K15: 2 | L15: ronadell.borromeo@telus.com | M15: Lo, Mamadou | N15: Pandza, Vinko | O15: 514-576-6788 | R15: MR2B | S15: M0080 | T15: L112660 | U15: 100956358 | V15: T956358 | X15: 15141294069 | Y15: 1063840 | AF15: 42227 | AG15: 19458 | AJ15: 1.00 - (34 - 37.5 Hours) | AK15: Operator | AL15: 46115 | AM15: 0.35416667 | AN15: 0.70833333 | AQ15: Ronadell | AR15: Borromeo | AS15: Alexandre Aubin - Giroux (conjoint) | AT15: 514-622-3627 | AY15: Ronadell Borromeo | BA15: 66930 | BB15: x | BC15: _ | BD15: x | BE15: x | BF15: _ | BG15: _ | BH15: x | BJ15: Morning (from 05h00 - 10h30) | BL15: 42531 | BM15: 42533 | BN15: Yes | BU15: No | BV15: Virtual | BW15: 35 | BX15: Full Time | BY15: 42349 | BZ15: Item | CA15: sites/SAM/Restricted_HUB/Lists/MEL
A16: 82 | B16: Brooks, Laura | C16: T956364 | D16: 956364 | E16: Active | F16: 41820 | H16: Monitoring Specialist II (Senior) | I16: Calgary | J16: English | K16: 4 | L16: laura.brooks@telus.com | M16: Coghiel, Caren | N16: Khara, Tanu | O16: 3688876400 | R16: CL4B | S16: M0082 | T16: L111968 | U16: 100956364 | V16: laurabrooks | X16: 14031292001 | Y16: 1210687 | AA16: Agent | AD16: Complaint Line;#7;#Question Line;#6;#SmartWear;#3;#Video Monitoring;#5;#SME;#11;#Basic Troubleshooting;#2 | AF16: 43126 | AG16: 25050 | AJ16: 1.00 - (34 - 37.5 Hours) | AK16: Operator | AL16: Week A (7/7) | AM16: 0.79166667 | AN16: 0.22916667 | AQ16: Laura | AR16: Brooks | AS16: Isabelle Chayer | AT16: 587-832-1969 | AU16: Friend | AV16: Rebecca Hebert | AW16: 403-619-1541 | AX16: Friend | AY16: Laura Brooks | BA16: 746559 | BB16: x | BC16: x | BD16: x | BE16: x | BF16: x | BG16: x | BH16: x | BJ16: Night (from 18h30 - 01h00) | BN16: Yes | BQ16: Yes | BU16: Yes | BV16: Mobile | BW16: 35 | BX16: Full Time | BZ16: Item | CA16: sites/SAM/Restricted_HUB/Lists/MEL
A17: 87 | B17: Calanza, Stevenson | C17: T955759 | D17: 955759 | E17: Active | F17: 43255 | H17: Monitoring Specialist II (Regular) | I17: Calgary | J17: English | K17: 2 | L17: stevenson.calanza@telus.com | M17: Gillingham, Shelley | N17: Khara, Tanu | O17: 403-620-2505 | R17: CS8C | S17: M0086 | T17: L111815 | U17: 100955759 | V17: scalanza | X17: 14031292135 | Y17: 1020213 | AD17: Basic Troubleshooting;#2 | AF17: 45218 | AG17: 968682 | AJ17: 1.00 - (34 - 37.5 Hours) | AK17: Operator | AL17: Week B (7/7) | AM17: 0.41666667 | AN17: 0.85416667 | AQ17: Stevenson | AR17: Calanza | AY17: Stevenson Calanza | BA17: 138998 | BB17: x | BC17: x | BD17: x | BE17: x | BF17: x | BG17: x | BH17: x | BJ17: Morning (from 05h00 - 10h30) | BL17: 43361 | BM17: 43482 | BN17: Yes | BR17: 44012 | BS17: 44063 | BU17: Yes | BV17: Virtual | BW17: 35 | BX17: Full Time | BY17: 43346 | BZ17: Item | CA17: sites/SAM/Restricted_HUB/Lists/MEL
A18: 637 | B18: Carl-Luigi Pierre | C18: T6001661 | D18: 6001661 | E18: Active | F18: 46146 | H18: Monitoring Specialist I (Junior) | I18: Ottawa | J18: Bilingual-French | K18: Trainee | L18: lugi.pierre@telus.com | M18: Diegue, Kerry | N18: Pandza, Vinko | O18: 5142161772 | T18: SD00S5EW | X18: 15141294022 | Y18: 1060068 | AJ18: 1.00 - (34 - 37.5 Hours) | AK18: Specialist - Hourly | AQ18: Carl-Luigi | AR18: Pierre | AY18: Carl-Luigi Pierre | BA18: Pending/Required | BB18: _ | BC18: _ | BD18: _ | BE18: _ | BF18: _ | BU18: No | BV18: In office | BW18: 35 | BX18: Full Time | BZ18: Item | CA18: sites/SAM/Restricted_HUB/Lists/MEL
A19: 89 | B19: Carvajal-Yiptong, Diego Armando | C19: T955811 | D19: 955811 | E19: Active | F19: 43948 | H19: Monitoring Specialist II (Senior) | I19: Montreal | J19: Bilingual-French | K19: 4 | L19: diego.carvajalyiptong@telus.com | M19: Dhindsa, Sukhjinder | N19: Khara, Tanu | O19: 438-828-1019 | R19: MD2C | S19: M0087 | T19: L112509 ( | U19: 100955811 | V19: diegocarvajalyipto | X19: 15141294253 | Y19: 1067281 | AA19: Agent | AD19: SmartWear;#3;#Basic Troubleshooting;#2;#Complaint Line;#7;#Question Line;#6;#Data Entry Advanced;#8;#Video Monitoring;#5 | AF19: 44404 | AG19: 32398 | AJ19: 1.00 - (34 - 37.5 Hours) | AK19: Operator | AL19: 46115 | AM19: 0.3125 | AN19: 0.66666667 | AQ19: Diego Armando | AR19: Carvajal-Yiptong | AY19: Diego Armando Carvajal-Yiptong | BA19: 66217 | BB19: _ | BC19: _ | BD19: x | BE19: x | BF19: _ | BG19: x | BH19: x | BJ19: Morning (from 05h00 - 10h30) | BL19: 44175 | BM19: 44390 | BN19: Yes | BO19: 45245 | BP19: 45443 | BQ19: Yes | BR19: 45846 | BS19: 45926 | BT19: Yes | BU19: No | BV19: Virtual | BW19: 34 | BX19: Full Time | BY19: 44019 | BZ19: Item | CA19: sites/SAM/Restricted_HUB/Lists/MEL
A20: 90 | B20: Cerdas Calvo, Deyanira | C20: T956355 | D20: 956355 | E20: Active | F20: 42611 | H20: Monitoring Specialist II (Regular) | I20: Calgary | J20: English | K20: 2 | L20: deyanira.cerdascalvo@telus.com | M20: Gillingham, Shelley | N20: Khara, Tanu | O20: 5876099254 | P20: 506-271-7858 | R20: CD4C | S20: M0088 | T20: L111647 | U20: 100956355 | V20: dcerdascalvo | X20: 14031292002 | Y20: 1020004 | AA20: Agent | AD20: SmartWear;#3 | AF20: 46053 | AG20: 972860 | AJ20: 1.00 - (34 - 37.5 Hours) | AK20: Operator | AL20: 46115 | AM20: 0.54166667 | AN20: 0.91666667 | AQ20: Deyanira | AR20: Cerdas Calvo | AY20: Deyanira Cerdas Calvo | BA20: 421171 | BB20: _ | BC20: x | BD20: x | BE20: _ | BF20: _ | BG20: x | BH20: x | BJ20: Evening (from 10h45 - 17h00) | BL20: 43728 | BN20: Yes | BU20: Yes | BV20: Virtual | BW20: 34 | BX20: Full Time | BY20: 43264 | BZ20: Item | CA20: sites/SAM/Restricted_HUB/Lists/MEL
A21: 576 | B21: Chan, Chinda | C21: T766860 | D21: 766860 | E21: Active | F21: 45544 | H21: Monitoring Specialist II (Regular) | I21: Montreal | J21: Bilingual-French | K21: 2 | L21: Chinda.Chan@telus.com | M21: Rwano, Guy Fremin | N21: Pandza, Vinko | O21: 4386995558 | S21: M0397 | T21: L705320 | U21: 100766860 | V21: T766860 | X21: 15141294058 | Y21: 1060052 | AF21: 45856 | AJ21: 1.00 - (34 - 37.5 Hours) | AK21: Specialist - Hourly | AL21: Week A (7/7) | AM21: 0.041666667 | AN21: 0.47916667 | AQ21: Chinda | AR21: Chan | AS21: TBD | AT21: TBD | AU21: TBD | AY21: Chinda Chan | BA21: 60007 | BB21: x | BC21: x | BD21: x | BE21: x | BF21: x | BG21: x | BH21: x | BJ21: Night (from 18h30 - 01h00) | BL21: 45673 | BM21: 45731 | BN21: Yes | BU21: No | BV21: Mobile | BW21: 34 | BX21: Full Time | BY21: 45619 | BZ21: Item | CA21: sites/SAM/Restricted_HUB/Lists/MEL
A22: 361 | B22: Chénard, William | C22: T995563 | D22: 995563 | E22: Active | F22: 44900 | H22: Monitoring Specialist II (Regular) | I22: Montreal | J22: Bilingual-French | K22: 2 | L22: william.chenard@telus.com | M22: Lo, Mamadou | N22: Pandza, Vinko | O22: 5148958430 | R22: MMW1C | S22: M0090 | T22: L111293 | U22: 100995563 | V22: T995563 | X22: 15141294037 | Y22: 1060011 | AF22: 45237 | AG22: 968897 | AJ22: 1.00 - (34 - 37.5 Hours) | AK22: Operator | AL22: 46115 | AM22: 0.25 | AN22: 0.60416667 | AQ22: William | AR22: Chénard | AY22: William Chénard | BA22: 60052 | BB22: x | BC22: _ | BD22: x | BE22: x | BF22: x | BG22: _ | BH22: _ | BJ22: Morning (from 05h00 - 10h30) | BL22: 45070 | BM22: 45168 | BN22: Yes | BU22: No | BV22: New | BW22: 34 | BX22: Full Time | BY22: 45041 | BZ22: Item | CA22: sites/SAM/Restricted_HUB/Lists/MEL
A23: 358 | B23: Chibane, Hakim | C23: T992448 | D23: 992448 | E23: Active | F23: 44823 | H23: Monitoring Specialist II (Senior) | I23: Remote Area | J23: French | K23: 4 | L23: hakim.chibane@telus.com | M23: Kollias, Peter | N23: Pandza, Vinko | O23: 9024414226 | R23: MRH1C | S23: M0091 | T23: L704858 | U23: 100992448 | V23: T992448 | X23: 15141294084 | Y23: 1066154 | AD23: Basic Troubleshooting;#2;#Question Line;#6;#Complaint Line;#7;#Video Monitoring;#5;#Video Verification;#4;#SME;#11 | AF23: 45357 | AG23: 969514 | AJ23: 1.00 - (34 - 37.5 Hours) | AK23: Operator | AL23: 46115 | AM23: 0.60416667 | AN23: 0.97916667 | AQ23: Hakim | AR23: Chibane | AS23: SI YOUCEF NACERA | AT23: 9029896481 | AY23: Hakim Chibane | BA23: Pending/Required | BB23: x | BC23: _ | BD23: _ | BE23: x | BF23: x | BG23: x | BH23: _ | BJ23: Evening (from 10h45 - 17h00) | BL23: 44967 | BM23: 45072 | BN23: Yes | BO23: 45924 | BP23: 45975 | BQ23: Yes | BR23: 46064 | BS23: 46136 | BT23: No | BU23: No | BV23: Virtual | BW23: 34 | BX23: Full Time | BY23: 44946 | BZ23: Item | CA23: sites/SAM/Restricted_HUB/Lists/MEL
A24: 645 | B24: Christian Langcuyan | C24: T6001712 | D24: 6001712 | E24: Active | F24: 46146 | H24: Monitoring Specialist I (Junior) | I24: Calgary | J24: English | K24: Trainee | L24: christian.langcuyan@telus.com | M24: Diegue, Kerry | N24: Pandza, Vinko | O24: 4039195377 | T24: SD00RRW2 | X24: 15141294049 | Y24: 1060074 | AJ24: 1.00 - (34 - 37.5 Hours) | AK24: Specialist - Hourly | AQ24: Christian | AR24: Langcuyan | AY24: Christian Langcuyan | BA24: Pending/Required | BB24: _ | BC24: _ | BD24: _ | BE24: _ | BF24: _ | BU24: Yes | BV24: In office | BW24: 35 | BX24: Full Time | BZ24: Item | CA24: sites/SAM/Restricted_HUB/Lists/MEL
A25: 624 | B25: Cobrana, Mechille | C25: T6001471 | D25: 6001471 | E25: Active | F25: 46119 | H25: Monitoring Specialist I (Junior) | I25: Calgary | J25: English | K25: 1 | L25: mechille.cobrana@telus.com | M25: Gillingham, Shelley | N25: Khara, Tanu | O25: 5879688694 | S25: M0535 | T25: SD00JKVD | U25: 106001471 | X25: 15141294039 | Y25: 1060013 | AJ25: 1.00 - (34 - 37.5 Hours) | AK25: Specialist - Hourly | AQ25: Mechille | AR25: Cobrana | AY25: Mechille Cobrana | BA25: 451832 | BB25: _ | BC25: _ | BD25: _ | BE25: _ | BF25: _ | BU25: Yes | BV25: In office | BW25: 35 | BX25: Full Time | BZ25: Item | CA25: sites/SAM/Restricted_HUB/Lists/MEL
A26: 353 | B26: Constant, Francesca | C26: T992326 | D26: 992326 | E26: Active | F26: 44823 | H26: Monitoring Specialist II (Regular) | I26: Montreal | J26: French | K26: 2 | L26: francesca.constant@telus.com | M26: Lo, Mamadou | N26: Pandza, Vinko | O26: 5145728590 | R26: MMF1C | S26: M0093 | T26: L111330 | U26: 100992326 | V26: T992326 | X26: 15141294080 | Y26: 1066150 | AD26: Basic Troubleshooting;#2 | AF26: 45546 | AG26: 992326 | AJ26: 1.00 - (34 - 37.5 Hours) | AK26: Operator | AL26: 46115 | AM26: 0.25 | AN26: 0.60416667 | AQ26: Francesca | AR26: Constant | AS26: Raymonde Jopseph. T | AT26: 514-348-2338 | AY26: Francesca Constant | BA26: 62341 | BB26: x | BC26: x | BD26: _ | BE26: _ | BF26: x | BG26: x | BH26: _ | BJ26: Morning (from 05h00 - 10h30) | BL26: 44965 | BM26: 45069 | BN26: Yes | BU26: No | BV26: Virtual | BW26: 35 | BX26: Full Time | BY26: 44960 | BZ26: Item | CA26: sites/SAM/Restricted_HUB/Lists/MEL
A27: 100 | B27: Daniels, Aeron | C27: T973078 | D27: 973078 | E27: Long Term Disability | F27: 43514 | H27: Monitoring Specialist II (Regular) | I27: Victoria | J27: English | K27: 2 | L27: aeron.daniels@telus.com | M27: Dhindsa, Sukhjinder | N27: Khara, Tanu | O27: 2508092089 | R27: MIA1D | S27: M0095 | T27: L805724 | U27: 100973078 | V27: t973078 | X27: 16041295067 | Y27: 1030138 | AC27: AERON.D | AD27: Basic Troubleshooting;#2 | AJ27: 1.00 - (34 - 37.5 Hours) | AK27: Operator | AL27: 46115 | AM27: 0.66666667 | AN27: 0 | AQ27: Aeron | AR27: Daniels | AY27: Aeron Daniels | BB27: x | BC27: _ | BD27: _ | BE27: _ | BF27: x | BG27: x | BH27: x | BJ27: Evening (from 10h45 - 17h00) | BL27: 44717 | BM27: 44717 | BN27: Yes | BU27: No | BV27: In office | BW27: 34 | BX27: Full Time | BY27: 44717 | BZ27: Item | CA27: sites/SAM/Restricted_HUB/Lists/MEL
A28: 101 | B28: Dansou, Senami | C28: T955704 | D28: 955704 | E28: Active | F28: 43045 | H28: Monitoring Specialist II (Regular) | I28: Ottawa | J28: Bilingual-French | K28: 4 | L28: senami.dansou@telus.com | M28: Rwano, Guy Fremin | N28: Pandza, Vinko | O28: 819-639-5002 | R28: OS2D | S28: M0096 | T28: L112614 | U28: 100955704 | V28: T955704 | X28: 16131293078 | Y28: 1062301 | AD28: Basic Troubleshooting;#2 | AF28: 43306 | AG28: 26262 | AJ28: 0.50 - (15 - 27 Hours) | AK28: Operator | AL28: Other / Casual | AM28: 0.6875 | AN28: 0.020833333 | AQ28: Senami | AR28: Dansou | AY28: Senami Dansou | BB28: _ | BC28: x | BD28: _ | BE28: _ | BF28: _ | BG28: _ | BH28: x | BJ28: Evening (from 10h45 - 17h00) | BL28: 43565 | BM28: 43567 | BN28: Yes | BO28: 43809 | BP28: 43811 | BQ28: Yes | BR28: 43944 | BS28: 43946 | BT28: Yes | BU28: No | BV28: Virtual | BW28: 21 | BX28: Part Time | BY28: 43424 | BZ28: Item | CA28: sites/SAM/Restricted_HUB/Lists/MEL
A29: 106 | B29: Deschineau, Shelsey Ann | C29: T966528 | D29: 966528 | E29: Active | F29: 44312 | H29: Monitoring Specialist II (Senior) | I29: Montreal | J29: Bilingual-French | K29: 4 | L29: shelsey.deschineau@telus.com | M29: Diegue, Kerry | N29: Pandza, Vinko | O29: 514-291-7884 | R29: MSAD | S29: M0099 | T29: New Asset L108071 Old asset L801333 | U29: 100966528 | V29: t966528 | X29: 15141294405 | Y29: 1066475 | AD29: Video Monitoring;#5;#Video Verification;#4;#Question Line;#6;#Complaint Line;#7;#Basic Troubleshooting;#2;#Video Monitoring Arpel only;#10 | AF29: 44693 | AG29: 34392 | AJ29: 1.00 - (34 - 37.5 Hours) | AK29: Operator | AL29: 46115 | AM29: 0.3125 | AN29: 0.66666667 | AQ29: Shelsey Ann | AR29: Deschineau | AS29: Marie-Gerline Charles | AT29: 514-291-7884 | AU29: Mother | AY29: Shelsey Ann Deschineau | BA29: 66104 | BB29: x | BC29: _ | BD29: _ | BE29: x | BF29: x | BG29: x | BH29: _ | BJ29: Morning (from 05h00 - 10h30) | BL29: 44650 | BM29: 44791 | BN29: Yes | BO29: 44945 | BP29: 45063 | BQ29: Yes | BR29: 44953 | BS29: 45077 | BT29: Yes | BU29: No | BV29: Virtual | BW29: 34 | BX29: Full Time | BY29: 44629 | BZ29: Item | CA29: sites/SAM/Restricted_HUB/Lists/MEL
A30: 108 | B30: Desjardins, Lucie | C30: T956365 | D30: 956365 | E30: Active | F30: 37788 | H30: Monitoring Specialist II (Senior) | I30: Montreal | J30: Bilingual-French | K30: 4 | L30: lucie.desjardins@telus.com | M30: Kollias, Peter | N30: Pandza, Vinko | O30: 5147731796 | R30: ML1D | S30: M0100 | T30: L112670 | U30: 100956365 | V30: ldesjardins | X30: 15141294090 | Y30: 1066097 | AD30: Complaint Line;#7;#Data Entry Advanced;#8;#Question Line;#6;#SME;#11 | AF30: 39956 | AG30: 4263 | AJ30: 1.00 - (34 - 37.5 Hours) | AK30: Operator | AL30: 46144 | AM30: 0.25 | AN30: 0.54166667 | AQ30: Lucie | AR30: Desjardins | AS30: Stephane Paradis | AT30: 514-249-8291 | AY30: Lucie Desjardins | BA30: 66075 | BB30: _ | BC30: x | BD30: x | BE30: x | BF30: x | BG30: x | BH30: _ | BI30: Non Standard | BJ30: Morning (from 05h00 - 10h30) | BN30: Yes | BQ30: Yes | BT30: Yes | BU30: No | BV30: Mobile | BW30: 35 | BX30: Full Time | BZ30: Item | CA30: sites/SAM/Restricted_HUB/Lists/MEL
A31: 611 | B31: Di Tullio, Donato | C31: T773558 | D31: 773558 | E31: Active | F31: 45957 | H31: Monitoring Specialist II (Regular) | I31: Montreal | J31: Bilingual-French | K31: 2 | L31: donato.ditullio@telus.com | M31: Herrati, Houcine | N31: Khara, Tanu | O31: 5149801223 | S31: M0510 | T31: PF5N9B0K | U31: 100773558 | X31: 15141294023 | Y31: 1060060 | AJ31: 1.00 - (34 - 37.5 Hours) | AK31: Operator | AL31: 46115 | AM31: 0.625 | AN31: 0 | AQ31: Donato | AR31: Di Tullio | AY31: Donato Di Tullio | BA31: Pending/Required | BB31: _ | BC31: _ | BD31: x | BE31: _ | BF31: x | BG31: x | BH31: x | BJ31: Evening (from 10h45 - 17h00) | BL31: 46049 | BM31: 46100 | BU31: No | BV31: Mobile | BX31: Full Time | BY31: 46031 | BZ31: Item | CA31: sites/SAM/Restricted_HUB/Lists/MEL
A32: 111 | B32: Dieu-Juste, Erica | C32: T956374 | D32: 956374 | E32: Long Term Disability | F32: 41239 | H32: Monitoring Specialist II (Senior) | I32: Montreal | J32: Bilingual-French | K32: 4 | L32: erica.dieu-juste@telus.com | M32: Lo, Mamadou | N32: Pandza, Vinko | O32: 514-677-8790 | R32: ME1D | S32: M0102 | T32: L112585 | U32: 100956374 | V32: edieujuste | X32: 15141294369 | Y32: 1066366 | AD32: Complaint Line;#7;#Question Line;#6;#Video Monitoring;#5;#Video Verification;#4 | AF32: 41599 | AG32: 14772 | AJ32: 1.00 - (34 - 37.5 Hours) | AK32: Operator | AL32: 46115 | AM32: 0.33333333 | AN32: 0.6875 | AQ32: Erica | AR32: Dieu-Juste | AY32: Erica Dieu-Juste | BA32: 66099 | BB32: _ | BC32: _ | BD32: x | BE32: x | BF32: x | BG32: _ | BH32: x | BJ32: Morning (from 05h00 - 10h30) | BN32: Yes | BO32: 44945 | BP32: 45033 | BQ32: Yes | BR32: 45237 | BU32: No | BV32: Virtual | BW32: 34 | BX32: Full Time | BZ32: Item | CA32: sites/SAM/Restricted_HUB/Lists/MEL
A33: 113 | B33: Doiron, Rejeanne | C33: T960871 | D33: 960871 | E33: Short Term Disability | F33: 44165 | H33: Monitoring Specialist II (Senior) | I33: Ottawa | J33: Bilingual-French | K33: 4 | L33: rejeanne.doiron@telus.com | M33: Rwano, Guy Fremin | N33: Pandza, Vinko | O33: 613-608-4223 | R33: OR2D | S33: M0104 | T33: L112067 | U33: 100960871 | V33: rejeannedoiron | X33: 16131293143 | Y33: 1066728 | AD33: Video Monitoring;#5;#Video Verification;#4;#Basic Troubleshooting;#2;#SmartWear;#3;#Complaint Line;#7;#Question Line;#6 | AF33: 44546 | AJ33: 1.00 - (34 - 37.5 Hours) | AK33: Operator | AL33: 46115 | AM33: 0.66666667 | AN33: 0.020833333 | AQ33: Rejeanne | AR33: Doiron | AY33: Rejeanne Doiron | BB33: x | BC33: x | BD33: _ | BE33: _ | BF33: x | BG33: x | BH33: _ | BJ33: Evening (from 10h45 - 17h00) | BL33: 44341 | BM33: 44384 | BN33: Yes | BO33: 45440 | BP33: 45556 | BQ33: Yes | BR33: 44982 | BS33: 45225 | BT33: Yes | BU33: No | BV33: Virtual | BW33: 35 | BX33: Full Time | BY33: 44314 | BZ33: Item | CA33: sites/SAM/Restricted_HUB/Lists/MEL
A34: 114 | B34: Dominique, Junia | C34: T956225 | D34: 956225 | E34: Short Term Disability | F34: 43114 | G34: 42989 | H34: Monitoring Specialist II (Senior) | I34: Montreal | J34: Bilingual-English | K34: 4 | L34: junia.dominique@telus.com | M34: Diegue, Kerry | N34: Pandza, Vinko | O34: 438-503-0886 | R34: MJ3D | S34: M0025 | T34: L112633 | U34: 100956225 | V34: jdominique | X34: 15141294123 | Y34: 1066734 | Z34: juniad | AA34: Supervisor | AC34: JDO | AD34: Complaint Line;#7;#Data Entry Advanced;#8;#Question Line;#6;#Backup MRC;#1;#Video Monitoring;#5;#Video Verification;#4;#Basic Troubleshooting;#2;#SmartWear;#3;#Video Monitoring Arpel only;#10 | AF34: 43173 | AG34: 25416 | AJ34: 1.00 - (34 - 37.5 Hours) | AK34: Specialist - Hourly | AL34: 46115 | AM34: 0.25 | AN34: 0.54166667 | AQ34: Junia | AR34: Dominique | AS34: Kaymisha | AT34: 5142951957 | AU34: Fille | AY34: Junia Dominique | BA34: 66119 | BB34: x | BC34: x | BD34: x | BE34: _ | BF34: x | BG34: _ | BH34: _ | BI34: Sunday 6:00 - 14:00 | BJ34: Morning (from 05h00 - 10h30) | BL34: 45529 | BM34: 45529 | BN34: Yes | BO34: 45529 | BP34: 45529 | BQ34: Yes | BR34: 45529 | BS34: 45529 | BT34: Yes | BU34: No | BV34: Mobile | BW34: 68 | BX34: Full Time | BY34: 45529 | BZ34: Item | CA34: sites/SAM/Restricted_HUB/Lists/MEL
A35: 615 | B35: Drame, Abdoulaye | C35: T773665 | D35: 773665 | E35: Active | F35: 45957 | H35: Monitoring Specialist II (Regular) | I35: Ottawa | J35: Bilingual-French | K35: 2 | L35: abdoulaye.drame@telus.com | M35: Dhindsa, Sukhjinder | N35: Khara, Tanu | O35: 6132952245 | S35: M0514 | T35: PF5N9B2R | U35: 100773665 | X35: 15141294008 | Y35: 1060063 | AJ35: 1.00 - (34 - 37.5 Hours) | AK35: Operator | AL35: Week A (7/7) | AM35: 0.66666667 | AN35: 0.10416667 | AQ35: Abdoulaye | AR35: Drame | AY35: Abdoulaye Drame | BA35: Pending/Required | BB35: x | BC35: x | BD35: x | BE35: x | BF35: x | BG35: x | BH35: x | BJ35: Evening (from 10h45 - 17h00) | BL35: 46056 | BM35: 46104 | BN35: Yes | BU35: No | BV35: Mobile | BX35: Full Time | BY35: 46038 | BZ35: Item | CA35: sites/SAM/Restricted_HUB/Lists/MEL
A36: 117 | B36: Dupuis, Joanie | C36: T956521 | D36: 956521 | E36: Active | F36: 43318 | H36: Monitoring Specialist II (Senior) | I36: Montreal | J36: Bilingual-French | K36: 4 | L36: joanie.dupuis@telus.com | M36: Diegue, Kerry | N36: Pandza, Vinko | O36: 514-568-8331 | R36: MJ6D | S36: M0107 | T36: L112629 | U36: 100956521 | V36: jdupuis | X36: 15141294050 | Y36: 1067025 | AD36: Video Monitoring;#5;#Video Verification;#4;#Complaint Line;#7;#Question Line;#6;#SmartWear;#3;#Video Monitoring Arpel only;#10;#Basic Troubleshooting;#2 | AF36: 43974 | AG36: 30414 | AJ36: 0.50 - (15 - 27 Hours) | AK36: Operator | AL36: Other / Casual | AM36: 0.29166667 | AN36: 0.64583333 | AQ36: Joanie | AR36: Dupuis | AS36: Nancy | AT36: 514-802-8950 | AU36: Mother | AV36: Serge | AW36: 514-568-8977 | AX36: Dad | AY36: Joanie Dupuis | BA36: 60036 | BB36: x | BC36: _ | BD36: _ | BE36: _ | BF36: _ | BG36: x | BH36: _ | BI36: part time schedule | BJ36: Morning (from 05h00 - 10h30) | BL36: 43478 | BM36: 43974 | BN36: Yes | BO36: 45440 | BP36: 45529 | BQ36: Yes | BR36: 44980 | BS36: 45074 | BT36: Yes | BU36: No | BV36: Virtual | BW36: 17 | BX36: Part Time | BY36: 43462 | BZ36: Item | CA36: sites/SAM/Restricted_HUB/Lists/MEL
A37: 412 | B37: El Hafsi, Hamza | C37: T996928 | D37: 996928 | E37: Active | F37: 44970 | H37: Monitoring Specialist II (Regular) | I37: Remote Area | J37: French | K37: 2 | L37: hamza.eihafsi@telus.com | M37: Diegue, Kerry | N37: Pandza, Vinko | O37: 4389510747 | S37: M0109 | T37: L801251 | U37: 100996928 | V37: T996928 | X37: 19051291052 | Y37: 1060028 | AJ37: 1.00 - (34 - 37.5 Hours) | AK37: Operator | AL37: Week A (7/7) | AM37: 0.94791667 | AN37: 0.38541667 | AQ37: Hamza | AR37: El Hafsi | AS37: Rania | AT37: 438-951-0746 | AU37: Wife | AY37: Hamza El Hafsi | BA37: Pending/Required | BB37: x | BC37: x | BD37: x | BE37: x | BF37: x | BG37: x | BH37: x | BJ37: Night (from 18h30 - 01h00) | BL37: 45204 | BM37: 45411 | BU37: No | BV37: Virtual | BW37: 35 | BX37: Full Time | BY37: 45085 | BZ37: Item | CA37: sites/SAM/Restricted_HUB/Lists/MEL
A38: 365 | B38: Fakhfakh, Souleymen | C38: T995918 | D38: 995918 | E38: Active | F38: 44900 | H38: Monitoring Specialist II (Senior) | I38: Remote Area | J38: French | K38: 4 | L38: souleymen.fakhfakh1@telus.com | M38: Diegue, Kerry | N38: Pandza, Vinko | O38: 5063807409 | R38: MRS1F | S38: M0111 | T38: L802309 | U38: 100995918 | V38: T995918 | X38: 19051291028 | Y38: 1110128 | AD38: Basic Troubleshooting;#2;#Complaint Line;#7;#Question Line;#6;#Video Monitoring;#5;#Video Monitoring Arpel only;#10;#Video Verification;#4 | AJ38: 1.00 - (34 - 37.5 Hours) | AK38: Operator | AL38: 46115 | AM38: 0.66666667 | AN38: 0.041666667 | AQ38: Souleymen | AR38: Fakhfakh | AS38: Faten Bouassida | AT38: 506-380-0655 | AY38: Souleymen Fakhfakh | BA38: Issued | BB38: _ | BC38: x | BD38: x | BE38: x | BF38: _ | BG38: _ | BH38: x | BJ38: Evening (from 10h45 - 17h00) | BL38: 45972 | BM38: 45972 | BN38: Yes | BO38: 45921 | BP38: 45921 | BQ38: No | BR38: 46056 | BS38: 46112 | BT38: No | BU38: No | BV38: Virtual | BW38: 37.5 | BX38: Full Time | BY38: 45035 | BZ38: Item | CA38: sites/SAM/Restricted_HUB/Lists/MEL
A39: 126 | B39: Flanagan-Fortin, Shawn | C39: T967974 | D39: 967974 | E39: Active | F39: 44337 | H39: Monitoring Specialist II (Senior) | I39: Vancouver | J39: English | K39: 4 | L39: shawn.flanagan-fortin@telus.com | M39: Dhindsa, Sukhjinder | N39: Khara, Tanu | O39: 7787911020 | R39: MVS1F | S39: M0113 | T39: L707513 (New) L806432(Old) | U39: 100967974 | V39: t967974 | X39: 16041295011 | Y39: 1067360 | Z39: sflanang | AD39: Backup MRC;#1;#Complaint Line;#7;#Question Line;#6;#SmartWear;#3;#Video Monitoring;#5;#Video Verification;#4 | AF39: 45030 | AG39: 35980 | AJ39: 1.00 - (34 - 37.5 Hours) | AK39: Operator | AL39: Week B (7/7) | AM39: 0.58333333 | AN39: 0.020833333 | AQ39: Shawn | AR39: Flanagan-Fortin | AS39: Carol-Ann Flanagan | AT39: 7788880977 | AU39: mom | AY39: Shawn Flanagan-Fortin | BA39: Issued | BB39: x | BC39: x | BD39: x | BE39: x | BF39: x | BG39: x | BH39: x | BJ39: Evening (from 10h45 - 17h00) | BL39: 44472 | BM39: 44472 | BN39: Yes | BO39: 44945 | BP39: 45172 | BQ39: Yes | BR39: 44953 | BS39: 45383 | BT39: Yes | BU39: No | BV39: In office | BW39: 35 | BX39: Full Time | BY39: 44472 | BZ39: Item | CA39: sites/SAM/Restricted_HUB/Lists/MEL
A40: 130 | B40: Gabriel, Gamelyn | C40: T955761 | D40: 955761 | E40: Active | F40: 42485 | H40: Monitoring Specialist II (Senior) | I40: Montreal | J40: Bilingual-French | K40: 4 | L40: gamelyn.gabriel@telus.com | M40: Rwano, Guy Fremin | N40: Pandza, Vinko | O40: 4382999631 | R40: MG2G | S40: M0115 | T40: L112361 | U40: 100955761 | V40: gamelyngabriel | X40: 15141294137 | Y40: 1066319 | AD40: Complaint Line;#7;#Data Entry Advanced;#8;#Question Line;#6;#Video Monitoring;#5;#Video Verification;#4;#Basic Troubleshooting;#2;#SmartWear;#3 | AF40: 42783 | AG40: 22353 | AJ40: 1.00 - (34 - 37.5 Hours) | AK40: Operator | AL40: 46115 | AM40: 0.75 | AN40: 0.10416667 | AQ40: Gamelyn | AR40: Gabriel | AS40: Ketly (conjointe) | AT40: 514-702-9884 | AY40: Gamelyn Gabriel | BB40: x | BC40: x | BD40: _ | BE40: x | BF40: x | BG40: _ | BH40: _ | BJ40: Evening (from 10h45 - 17h00) | BN40: Yes | BQ40: Yes | BT40: Yes | BU40: No | BV40: Mobile | BW40: 34 | BX40: Full Time | BZ40: Item | CA40: sites/SAM/Restricted_HUB/Lists/MEL
...

Sheet Current_Stats
A1: Agent | B1: Month of Ref Date | C1: Nb Worked Days | D1: Login (hr) | E1: In & Out by hr | F1: Total All Calls | G1: Inbound Time % | H1: Outbound Time % | I1: nb Transfers | J1: % Transf on Queue Calls | K1: Nb Calls Answ | L1: AHT | M1: Avg Talk Time | N1: Avg Hold Time | O1: Avg ACW Total | P1: Avg ACW to Calls | Q1: Outbound Calls | R1: Avg Talk Time Out | S1: Nb Extension In Calls | T1: Avg Talk Time Ext In
A2: Grand Total | C2: 1339 | D2: 8304.7 | E2: 12.4 | F2: 102599 | G2: 0.62 | H2: 0.38 | I2: 1086 | J2: 0.044 | K2: 24871 | L2: 0.0017653 | M2: 0.0011965 | N2: 0.0001496 | O2: 0.0004207 | P2: 0.0004207 | Q2: 77630 | R2: 0.0008561 | S2: 98 | T2: 0.0011755
A3: Abouda, Mohammed | B3: 46113 | C3: 14 | D3: 129 | E3: 17.1 | F3: 2208 | G3: 0.494 | H3: 0.506 | I3: 36 | J3: 0.056 | K3: 647 | L3: 0.0017509 | M3: 0.0012768 | N3: 0.0003625 | O3: 0.0001561 | P3: 0.0001561 | Q3: 1561 | R3: 0.0007344 | S3: 0
A4: Aidoud, Nabil | B4: 46113 | C4: 14 | D4: 117.7 | E4: 7.5 | F4: 880 | G4: 0.803 | H4: 0.197 | I4: 17 | J4: 0.057 | K4: 298 | L4: 0.0013444 | M4: 0.0010008 | N4: 9.873e-05 | O4: 0.000267 | P4: 0.000267 | Q4: 581 | R4: 0.0008228 | S4: 1 | T4: 0.0002199
A5: Akherraz, Hajar | B5: 46113 | C5: 23 | D5: 118.5 | E5: 6.7 | F5: 799 | G5: 0.556 | H5: 0.444 | I5: 3 | J5: 0.024 | K5: 126 | L5: 0.0020068 | M5: 0.0013315 | N5: 0.0003631 | O5: 0.0002821 | P5: 0.0002821 | Q5: 671 | R5: 0.0007069 | S5: 2 | T5: 0.0005498
A6: Aquilario, Lester | B6: 46113 | C6: 13 | D6: 100.3 | E6: 12.9 | F6: 1293 | G6: 0.31 | H6: 0.69 | I6: 9 | J6: 0.055 | K6: 164 | L6: 0.0019094 | M6: 0.0012117 | N6: 0.0002248 | O6: 0.0005624 | P6: 0.0005624 | Q6: 1129 | R6: 0.0008603 | S6: 0
A7: Audet, Dominic | B7: 46113 | C7: 22 | D7: 102.6 | E7: 11.8 | F7: 1208 | G7: 0.921 | H7: 0.079 | I7: 3 | J7: 0.023 | K7: 128 | L7: 0.0017381 | M7: 0.0014837 | N7: 0.0002407 | O7: 0.0001502 | P7: 0.0001502 | Q7: 1079 | R7: 0.0008689 | S7: 1 | T7: 0.0015625
A8: Auger, Adrien | B8: 46113 | C8: 16 | D8: 129.1 | E8: 11 | F8: 1422 | G8: 0.677 | H8: 0.323 | I8: 9 | J8: 0.023 | K8: 395 | L8: 0.0015833 | M8: 0.001033 | N8: 3.138e-05 | O8: 0.0004718 | P8: 0.0004718 | Q8: 1027 | R8: 0.0008949 | S8: 0
A9: Baisi, Jean-Gabriel | B9: 46113 | C9: 14 | D9: 128.2 | E9: 15.1 | F9: 1939 | G9: 0.295 | H9: 0.705 | I9: 10 | J9: 0.047 | K9: 213 | L9: 0.0027823 | M9: 0.0018832 | N9: 0.0007685 | O9: 0.0004489 | P9: 0.0004489 | Q9: 1722 | R9: 0.001145 | S9: 4 | T9: 0.0010735
A10: Bercier, France | B10: 46113 | C10: 12 | D10: 85.4 | E10: 18.9 | F10: 1615 | G10: 0.546 | H10: 0.454 | I10: 2 | J10: 0.071 | K10: 28 | L10: 0.0023727 | M10: 0.0020217 | N10: 0.000735 | O10: 0.0002464 | P10: 0.0002464 | Q10: 1586 | R10: 0.0009868 | S10: 1 | T10: 0.0004282
A11: Borromeo, Ronadell | B11: 46113 | C11: 14 | D11: 98.9 | E11: 10.9 | F11: 1076 | G11: 0.839 | H11: 0.161 | I11: 28 | J11: 0.038 | K11: 732 | L11: 0.0025817 | M11: 0.0017959 | N11: 0.000124 | O11: 0.0006225 | P11: 0.0006225 | Q11: 341 | R11: 0.0011186 | S11: 3 | T11: 0.0005594
A12: Brar, Dilpreet Kaur | B12: 46113 | C12: 8 | D12: 14.4 | E12: 2.2 | F12: 31 | G12: 0.222 | H12: 0.778 | I12: 0 | K12: 0 | Q12: 30 | R12: 0.0012157 | S12: 1 | T12: 0.0003125
A13: Brooks, Laura | B13: 46113 | C13: 9 | D13: 66.6 | E13: 7 | F13: 463 | G13: 0.515 | H13: 0.485 | I13: 7 | J13: 0.055 | K13: 128 | L13: 0.0025617 | M13: 0.0019273 | N13: 5.561e-05 | O13: 0.000466 | P13: 0.000466 | Q13: 335 | R13: 0.0011696 | S13: 0
A14: Calanza, Stevenson | B14: 46113 | C14: 14 | D14: 127.1 | E14: 20.6 | F14: 2612 | G14: 0.34 | H14: 0.66 | I14: 38 | J14: 0.078 | K14: 485 | L14: 0.001729 | M14: 0.0007517 | N14: 0.0001273 | O14: 0.0007085 | P14: 0.0007085 | Q14: 2126 | R14: 0.0004255 | S14: 1 | T14: 0.0001505
A15: Carvajal Yiptong, Diego Armando | B15: 46113 | C15: 13 | D15: 91.6 | E15: 11.7 | F15: 1070 | G15: 0.857 | H15: 0.143 | I15: 37 | J15: 0.08 | K15: 461 | L15: 0.0017906 | M15: 0.0012217 | N15: 0.0003322 | O15: 0.0003199 | P15: 0.0003199 | Q15: 608 | R15: 0.0009023 | S15: 1 | T15: 0.0004745
A16: Cerdas Calvo, Deyanira | B16: 46113 | C16: 16 | D16: 100.4 | E16: 16.5 | F16: 1661 | G16: 0.213 | H16: 0.787 | I16: 19 | J16: 0.099 | K16: 192 | L16: 0.0019162 | M16: 0.0015368 | N16: 0.0004798 | O16: 0.0001546 | P16: 0.0001546 | Q16: 1469 | R16: 0.0009032 | S16: 0
A17: Chan, Chinda | B17: 46113 | C17: 14 | D17: 128.1 | E17: 11.2 | F17: 1441 | G17: 0.59 | H17: 0.41 | I17: 12 | J17: 0.022 | K17: 548 | L17: 0.0019359 | M17: 0.0011224 | N17: 9.401e-05 | O17: 0.0007146 | P17: 0.0007146 | Q17: 891 | R17: 0.0009605 | S17: 2 | T17: 0.0003472
A18: Chenard, William | B18: 46113 | C18: 14 | D18: 90.5 | E18: 15.3 | F18: 1382 | G18: 0.601 | H18: 0.399 | I18: 39 | J18: 0.063 | K18: 618 | L18: 0.0014945 | M18: 0.0008982 | N18: 6.424e-05 | O18: 0.0004919 | P18: 0.0004919 | Q18: 764 | R18: 0.0008178 | S18: 0
A19: Chibane, Hakim | B19: 46113 | C19: 16 | D19: 127 | E19: 15.1 | F19: 1913 | G19: 0.608 | H19: 0.392 | I19: 12 | J19: 0.096 | K19: 125 | L19: 0.0032145 | M19: 0.0019044 | N19: 0.0008107 | O19: 0.0009081 | P19: 0.0009081 | Q19: 1788 | R19: 0.0008585 | S19: 0
A20: Cobrana, Mechille | B20: 46113 | C20: 7 | D20: 8.6 | E20: 4.4 | F20: 38 | G20: 0 | H20: 1 | I20: 0 | K20: 0 | Q20: 37 | R20: 0.00092 | S20: 1 | T20: 0.0001157
A21: Constant, Francesca | B21: 46113 | C21: 12 | D21: 77.6 | E21: 15.1 | F21: 1174 | G21: 0.381 | H21: 0.619 | I21: 17 | J21: 0.108 | K21: 158 | L21: 0.0020302 | M21: 0.0014925 | N21: 0.0004107 | O21: 0.0003622 | P21: 0.0003622 | Q21: 1015 | R21: 0.0008973 | S21: 1 | T21: 0.0003819
A22: Dansou, Senami Patrick | B22: 46113 | C22: 10 | D22: 36.2 | E22: 16.7 | F22: 606 | G22: 0.409 | H22: 0.591 | I22: 5 | J22: 0.044 | K22: 114 | L22: 0.0019322 | M22: 0.0009278 | N22: 6.396e-05 | O22: 0.0009194 | P22: 0.0009194 | Q22: 490 | R22: 0.000753 | S22: 2 | T22: 0.0003877
A23: Dazulme, Wildile | B23: 46113 | C23: 24 | D23: 96.8 | E23: 9.2 | F23: 887 | G23: 0.688 | H23: 0.312 | I23: 0 | J23: 0 | K23: 442 | L23: 0.0013176 | M23: 0.0010869 | N23: 8.641e-07 | O23: 0.0001874 | P23: 0.0001874 | Q23: 445 | R23: 0.0008474 | S23: 0
A24: Deschineau, Shelsey Ann | B24: 46113 | C24: 11 | D24: 69.4 | E24: 15.4 | F24: 1071 | G24: 0.51 | H24: 0.49 | I24: 11 | J24: 0.044 | K24: 248 | L24: 0.0020848 | M24: 0.0011995 | N24: 9.399e-05 | O24: 0.0007989 | P24: 0.0007989 | Q24: 820 | R24: 0.0008302 | S24: 3 | T24: 0.0002083
A25: Desjardins, Lucie | B25: 46113 | C25: 19 | D25: 105.2 | E25: 21.1 | F25: 2217 | G25: 0.887 | H25: 0.113 | I25: 4 | J25: 0.032 | K25: 126 | L25: 0.0014397 | M25: 0.0010727 | N25: 0.0001461 | O25: 0.0003033 | P25: 0.0003033 | Q25: 2091 | R25: 0.0007548 | S25: 0
A26: Di Tullio, Donato | B26: 46113 | C26: 24 | D26: 127.4 | E26: 18.4 | F26: 2348 | G26: 0.529 | H26: 0.471 | I26: 35 | J26: 0.047 | K26: 745 | L26: 0.0014368 | M26: 0.0009521 | N26: 4.111e-05 | O26: 0.0004449 | P26: 0.0004449 | Q26: 1603 | R26: 0.0008311 | S26: 0
A27: Drame, Abdoulaye | B27: 46113 | C27: 16 | D27: 130 | E27: 16.6 | F27: 2154 | G27: 0.435 | H27: 0.565 | I27: 9 | J27: 0.02 | K27: 444 | L27: 0.0020111 | M27: 0.0011113 | N27: 8.725e-05 | O27: 0.0006482 | P27: 0.0006482 | Q27: 1710 | R27: 0.0008619 | S27: 0
A28: Dupuis, Joanie | B28: 46113 | C28: 8 | D28: 51.3 | E28: 12.8 | F28: 655 | G28: 0.919 | H28: 0.081 | I28: 11 | J28: 0.045 | K28: 243 | L28: 0.0017827 | M28: 0.0009278 | N28: 0.0005713 | O28: 0.0004175 | P28: 0.0004175 | Q28: 410 | R28: 0.0008262 | S28: 2 | T28: 0.0001331
A29: El Hafsi, Hamza | B29: 46113 | C29: 15 | D29: 109.4 | E29: 8 | F29: 878 | G29: 0.415 | H29: 0.585 | I29: 2 | J29: 0.017 | K29: 118 | L29: 0.0018332 | M29: 0.0010017 | N29: 5.846e-05 | O29: 0.0006706 | P29: 0.0006706 | Q29: 760 | R29: 0.0008024 | S29: 0
A30: Fakhfakh, Souleymen | B30: 46113 | C30: 18 | D30: 82.4 | E30: 10.2 | F30: 838 | G30: 0.964 | H30: 0.036 | I30: 26 | J30: 0.104 | K30: 250 | L30: 0.0017722 | M30: 0.001344 | N30: 0.0004491 | O30: 0.0001079 | P30: 0.0001079 | Q30: 588 | R30: 0.0009243 | S30: 0
A31: Flanagan-Fortin, Shawn | B31: 46113 | C31: 7 | D31: 51.3 | E31: 6.1 | F31: 314 | G31: 0.632 | H31: 0.368 | I31: 0 | J31: 0 | K31: 64 | L31: 0.0006491 | M31: 0.000434 | N31: 6.872e-06 | O31: 0.0002148 | P31: 0.0002148 | Q31: 247 | R31: 0.0007303 | S31: 3 | T31: 0.000409
A32: Gabriel, Gamelyn | B32: 46113 | C32: 9 | D32: 31.1 | E32: 6.6 | F32: 206 | G32: 0.829 | H32: 0.171 | I32: 3 | J32: 0.061 | K32: 49 | L32: 0.0021072 | M32: 0.0018679 | N32: 0.0001301 | O32: 0.000149 | P32: 0.000149 | Q32: 156 | R32: 0.001027 | S32: 1 | T32: 0.0011227
A33: Gagnon, Nancy | B33: 46113 | C33: 18 | D33: 110.6 | E33: 7.4 | F33: 823 | G33: 0.765 | H33: 0.235 | I33: 1 | J33: 0.005 | K33: 184 | L33: 0.0016993 | M33: 0.0015622 | N33: 3.063e-05 | O33: 0.000112 | P33: 0.000112 | Q33: 638 | R33: 0.0008161 | S33: 1 | T33: 0.0086227
A34: Gil Cervino, Henrique Alexandre | B34: 46113 | C34: 9 | D34: 40 | E34: 3.1 | F34: 123 | G34: 0.845 | H34: 0.155 | I34: 1 | J34: 0.04 | K34: 25 | L34: 0.0026699 | M34: 0.0019417 | N34: 0.0003222 | O34: 0.0003838 | P34: 0.0003838 | Q34: 98 | R34: 0.0010482 | S34: 0
A35: Ginete, Maricel | B35: 46113 | C35: 7 | D35: 8.7 | E35: 4.6 | F35: 40 | G35: 0.455 | H35: 0.545 | I35: 0 | K35: 0 | Q35: 40 | R35: 0.0009112 | S35: 0
A36: Goddard, Adrien | B36: 46113 | C36: 12 | D36: 76.9 | E36: 14.2 | F36: 1089 | G36: 1 | H36: 0 | I36: 3 | J36: 0.019 | K36: 156 | L36: 0.0024484 | M36: 0.0012292 | N36: 0.0001483 | O36: 0.000346 | P36: 0.000346 | Q36: 931 | R36: 0.0010376 | S36: 2 | T36: 0.0001273
A37: Guzman, Alexandre | B37: 46113 | C37: 12 | D37: 100 | E37: 12.7 | F37: 1266 | G37: 0.622 | H37: 0.378 | I37: 19 | J37: 0.036 | K37: 525 | L37: 0.0018796 | M37: 0.0012131 | N37: 0.0001715 | O37: 0.000516 | P37: 0.000516 | Q37: 741 | R37: 0.000963 | S37: 0
A38: Herbst, Emily Blythe | B38: 46113 | C38: 13 | D38: 87.5 | E38: 12 | F38: 1051 | G38: 0.474 | H38: 0.526 | I38: 0 | J38: 0 | K38: 88 | L38: 0.0009113 | M38: 0.0007694 | N38: 9.917e-05 | O38: 0.0001299 | P38: 0.0001299 | Q38: 959 | R38: 0.0008703 | S38: 4 | T38: 0.0024855
A39: Hirst-Smith, Courtnay | B39: 46113 | C39: 16 | D39: 124.4 | E39: 13.4 | F39: 1665 | G39: 0.548 | H39: 0.452 | I39: 6 | J39: 0.045 | K39: 132 | L39: 0.0024048 | M39: 0.0014041 | N39: 0.0012834 | O39: 0.0005306 | P39: 0.0005306 | Q39: 1532 | R39: 0.0011585 | S39: 1 | T39: 0.0004861
A40: Hirwa, Jules Adam | B40: 46113 | C40: 11 | D40: 74.3 | E40: 11.5 | F40: 855 | G40: 0.694 | H40: 0.306 | I40: 10 | J40: 0.034 | K40: 290 | L40: 0.0022001 | M40: 0.0015014 | N40: 0.0002508 | O40: 0.0005087 | P40: 0.0005087 | Q40: 563 | R40: 0.0010227 | S40: 2 | T40: 0.0002778
...

Sheet Previous_Stats
A1: Agent | B1: Month of Ref Date | C1: Nb Worked Days | D1: Login (hr) | E1: In & Out by hr | F1: Total All Calls | G1: Inbound Time % | H1: Outbound Time % | I1: nb Transfers | J1: % Transf on Queue Calls | K1: Nb Calls Answ | L1: AHT | M1: Avg Talk Time | N1: Avg Hold Time | O1: Avg ACW Total | P1: Avg ACW to Calls | Q1: Outbound Calls | R1: Avg Talk Time Out | S1: Nb Extension In Calls | T1: Avg Talk Time Ext In
A2: Grand Total | C2: 798 | D2: 5076.5 | E2: 12.3 | F2: 62348 | G2: 0.619 | H2: 0.381 | I2: 655 | J2: 0.043 | K2: 15102 | L2: 0.0017467 | M2: 0.0011889 | N2: 0.000149 | O2: 0.0004129 | P2: 0.0004129 | Q2: 47190 | R2: 0.0008475 | S2: 56 | T2: 0.001577
A3: Abouda, Mohammed | B3: 46113 | C3: 9 | D3: 82.2 | E3: 15 | F3: 1230 | G3: 0.595 | H3: 0.405 | I3: 26 | J3: 0.053 | K3: 494 | L3: 0.0017665 | M3: 0.0012762 | N3: 0.0003716 | O3: 0.0001689 | P3: 0.0001689 | Q3: 736 | R3: 0.0007694 | S3: 0
A4: Aidoud, Nabil | B4: 46113 | C4: 9 | D4: 73.1 | E4: 10.2 | F4: 749 | G4: 0.699 | H4: 0.301 | I4: 14 | J4: 0.064 | K4: 219 | L4: 0.0014458 | M4: 0.0010665 | N4: 0.0001216 | O4: 0.0002956 | P4: 0.0002956 | Q4: 530 | R4: 0.0008306 | S4: 0
A5: Akherraz, Hajar | B5: 46113 | C5: 13 | D5: 64.7 | E5: 6.3 | F5: 407 | G5: 0.651 | H5: 0.349 | I5: 1 | J5: 0.012 | K5: 85 | L5: 0.0018521 | M5: 0.0011541 | N5: 0.00041 | O5: 0.0002888 | P5: 0.0002888 | Q5: 320 | R5: 0.0007124 | S5: 2 | T5: 0.0005498
A6: Aquilario, Lester | B6: 46113 | C6: 8 | D6: 62 | E6: 14.5 | F6: 897 | G6: 0.366 | H6: 0.634 | I6: 8 | J6: 0.06 | K6: 133 | L6: 0.0019573 | M6: 0.001188 | N6: 0.0002085 | O6: 0.00061 | P6: 0.00061 | Q6: 764 | R6: 0.0009002 | S6: 0
A7: Audet, Dominic | B7: 46113 | C7: 14 | D7: 60.3 | E7: 12.3 | F7: 741 | G7: 0.906 | H7: 0.094 | I7: 2 | J7: 0.03 | K7: 66 | L7: 0.0015837 | M7: 0.0012949 | N7: 0.0002632 | O7: 0.0001563 | P7: 0.0001563 | Q7: 674 | R7: 0.0008689 | S7: 1 | T7: 0.0015625
A8: Auger, Adrien | B8: 46113 | C8: 10 | D8: 76.8 | E8: 10.6 | F8: 815 | G8: 0.732 | H8: 0.268 | I8: 7 | J8: 0.026 | K8: 270 | L8: 0.0014504 | M8: 0.0010293 | N8: 1.878e-05 | O8: 0.0003721 | P8: 0.0003721 | Q8: 545 | R8: 0.0008561 | S8: 0
A9: Baisi, Jean-Gabriel | B9: 46113 | C9: 8 | D9: 73 | E9: 17.2 | F9: 1258 | G9: 0.133 | H9: 0.867 | I9: 3 | J9: 0.068 | K9: 44 | L9: 0.0028806 | M9: 0.0016627 | N9: 0.0023593 | O9: 0.0003801 | P9: 0.0003801 | Q9: 1212 | R9: 0.0011389 | S9: 2 | T9: 0.0021354
A10: Bercier, France | B10: 46113 | C10: 6 | D10: 46.9 | E10: 19.7 | F10: 922 | G10: 0.625 | H10: 0.375 | I10: 1 | J10: 0.043 | K10: 23 | L10: 0.0022459 | M10: 0.0019213 | N10: 0.00055 | O10: 0.0002687 | P10: 0.0002687 | Q10: 898 | R10: 0.0009676 | S10: 1 | T10: 0.0004282
A11: Borromeo, Ronadell | B11: 46113 | C11: 7 | D11: 49.9 | E11: 11.2 | F11: 558 | G11: 0.829 | H11: 0.171 | I11: 12 | J11: 0.032 | K11: 371 | L11: 0.0025946 | M11: 0.001762 | N11: 0.0001511 | O11: 0.0006479 | P11: 0.0006479 | Q11: 184 | R11: 0.0009822 | S11: 3 | T11: 0.0005594
A12: Brar, Dilpreet Kaur | B12: 46113 | C12: 2 | D12: 0.1 | E12: 24.6 | F12: 2 | G12: 0 | H12: 1 | I12: 0 | K12: 0 | Q12: 1 | R12: 0.0003241 | S12: 1 | T12: 0.0003125
A13: Brooks, Laura | B13: 46113 | C13: 9 | D13: 66.6 | E13: 7 | F13: 463 | G13: 0.515 | H13: 0.485 | I13: 7 | J13: 0.055 | K13: 128 | L13: 0.0025617 | M13: 0.0019273 | N13: 5.561e-05 | O13: 0.000466 | P13: 0.000466 | Q13: 335 | R13: 0.0011696 | S13: 0
A14: Calanza, Stevenson | B14: 46113 | C14: 9 | D14: 85.9 | E14: 20.9 | F14: 1792 | G14: 0.26 | H14: 0.74 | I14: 16 | J14: 0.064 | K14: 251 | L14: 0.0017433 | M14: 0.0007682 | N14: 0.0001446 | O14: 0.0007254 | P14: 0.0007254 | Q14: 1540 | R14: 0.0004599 | S14: 1 | T14: 0.0001505
A15: Carvajal Yiptong, Diego Armando | B15: 46113 | C15: 8 | D15: 55.3 | E15: 10.7 | F15: 593 | G15: 0.937 | H15: 0.063 | I15: 30 | J15: 0.088 | K15: 340 | L15: 0.0018292 | M15: 0.0012425 | N15: 0.0002272 | O15: 0.0003439 | P15: 0.0003439 | Q15: 252 | R15: 0.0008763 | S15: 1 | T15: 0.0004745
A16: Cerdas Calvo, Deyanira | B16: 46113 | C16: 9 | D16: 58 | E16: 15.9 | F16: 925 | G16: 0.189 | H16: 0.811 | I16: 8 | J16: 0.09 | K16: 89 | L16: 0.001988 | M16: 0.0015289 | N16: 0.0005951 | O16: 0.0001875 | P16: 0.0001875 | Q16: 836 | R16: 0.0009032 | S16: 0
A17: Chan, Chinda | B17: 46113 | C17: 8 | D17: 73.8 | E17: 11.1 | F17: 822 | G17: 0.648 | H17: 0.352 | I17: 6 | J17: 0.017 | K17: 349 | L17: 0.0019464 | M17: 0.0011315 | N17: 0.0001006 | O17: 0.0007131 | P17: 0.0007131 | Q17: 473 | R17: 0.0009914 | S17: 0
A18: Chenard, William | B18: 46113 | C18: 9 | D18: 61.7 | E18: 16 | F18: 986 | G18: 0.514 | H18: 0.486 | I18: 22 | J18: 0.058 | K18: 381 | L18: 0.0014224 | M18: 0.0008504 | N18: 9.651e-05 | O18: 0.0004585 | P18: 0.0004585 | Q18: 605 | R18: 0.0008112 | S18: 0
A19: Chibane, Hakim | B19: 46113 | C19: 11 | D19: 87.6 | E19: 14.9 | F19: 1309 | G19: 0.549 | H19: 0.451 | I19: 7 | J19: 0.079 | K19: 89 | L19: 0.0031921 | M19: 0.0019641 | N19: 0.0004267 | O19: 0.0009902 | P19: 0.0009902 | Q19: 1220 | R19: 0.000836 | S19: 0
A20: Cobrana, Michelle | B20: 46113 | C20: 3 | D20: 3.2 | E20: 0.3 | F20: 1 | G20: 0 | H20: 1 | I20: 0 | K20: 0 | Q20: 1 | R20: 0.0001157 | S20: 0
A21: Constant, Francesca | B21: 46113 | C21: 8 | D21: 52.2 | E21: 16.3 | F21: 849 | G21: 0.239 | H21: 0.761 | I21: 9 | J21: 0.176 | K21: 51 | L21: 0.0024483 | M21: 0.0017202 | N21: 0.0010296 | O21: 0.0003334 | P21: 0.0003334 | Q21: 797 | R21: 0.0009254 | S21: 1 | T21: 0.0003819
A22: Dansou, Senami Patrick | B22: 46113 | C22: 6 | D22: 22.5 | E22: 16.9 | F22: 379 | G22: 0.059 | H22: 0.941 | I22: 1 | J22: 0.091 | K22: 11 | L22: 0.001572 | M22: 0.0008154 | N22: 0.000282 | O22: 0.0006587 | P22: 0.0006587 | Q22: 366 | R22: 0.0007547 | S22: 2 | T22: 0.0003877
A23: Dazulme, Wildile | B23: 46113 | C23: 15 | D23: 68.5 | E23: 9.1 | F23: 621 | G23: 0.8 | H23: 0.2 | I23: 0 | J23: 0 | K23: 385 | L23: 0.0013475 | M23: 0.0011071 | N23: 9.921e-07 | O23: 0.0001975 | P23: 0.0001975 | Q23: 236 | R23: 0.0008566 | S23: 0
A24: Deschineau, Shelsey Ann | B24: 46113 | C24: 7 | D24: 44.6 | E24: 15.9 | F24: 710 | G24: 0.413 | H24: 0.587 | I24: 4 | J24: 0.038 | K24: 106 | L24: 0.0022647 | M24: 0.0012657 | N24: 0.00016 | O24: 0.0008741 | P24: 0.0008741 | Q24: 603 | R24: 0.0008294 | S24: 1 | T24: 0.0002083
A25: Desjardins, Lucie | B25: 46113 | C25: 12 | D25: 72.1 | E25: 20.9 | F25: 1503 | G25: 0.936 | H25: 0.064 | I25: 0 | J25: 0 | K25: 51 | L25: 0.0015525 | M25: 0.0011007 | N25: 0.0002483 | O25: 0.0003504 | P25: 0.0003504 | Q25: 1452 | R25: 0.0007587 | S25: 0
A26: Di Tullio, Donato | B26: 46113 | C26: 15 | D26: 79.8 | E26: 19.3 | F26: 1537 | G26: 0.49 | H26: 0.51 | I26: 17 | J26: 0.036 | K26: 469 | L26: 0.0013931 | M26: 0.0009178 | N26: 3.781e-05 | O26: 0.0004384 | P26: 0.0004384 | Q26: 1068 | R26: 0.0008062 | S26: 0
A27: Drame, Abdoulaye | B27: 46113 | C27: 10 | D27: 75.6 | E27: 16.9 | F27: 1274 | G27: 0.373 | H27: 0.627 | I27: 5 | J27: 0.022 | K27: 227 | L27: 0.0019688 | M27: 0.0011954 | N27: 0.0001175 | O27: 0.0006552 | P27: 0.0006552 | Q27: 1047 | R27: 0.0008652 | S27: 0
A28: Dupuis, Joanie | B28: 46113 | C28: 5 | D28: 30.3 | E28: 10.9 | F28: 330 | G28: 0.867 | H28: 0.133 | I28: 5 | J28: 0.098 | K28: 51 | L28: 0.0021262 | M28: 0.0010242 | N28: 0.0011222 | O28: 0.0002685 | P28: 0.0002685 | Q28: 278 | R28: 0.0008073 | S28: 1 | T28: 0.0001273
A29: El Hafsi, Hamza | B29: 46113 | C29: 8 | D29: 52.5 | E29: 7.5 | F29: 392 | G29: 0.397 | H29: 0.603 | I29: 2 | J29: 0.031 | K29: 65 | L29: 0.0018408 | M29: 0.0011163 | N29: 8.743e-05 | O29: 0.0006385 | P29: 0.0006385 | Q29: 327 | R29: 0.0008363 | S29: 0
A30: Fakhfakh, Souleymen | B30: 46113 | C30: 9 | D30: 43.1 | E30: 9 | F30: 387 | G30: 0.948 | H30: 0.052 | I30: 17 | J30: 0.103 | K30: 165 | L30: 0.001607 | M30: 0.0013122 | N30: 0.0001978 | O30: 9.989e-05 | P30: 9.989e-05 | Q30: 222 | R30: 0.0008985 | S30: 0
A31: Flanagan-Fortin, Shawn | B31: 46113 | C31: 7 | D31: 51.3 | E31: 6.1 | F31: 314 | G31: 0.632 | H31: 0.368 | I31: 0 | J31: 0 | K31: 64 | L31: 0.0006491 | M31: 0.000434 | N31: 6.872e-06 | O31: 0.0002148 | P31: 0.0002148 | Q31: 247 | R31: 0.0007303 | S31: 3 | T31: 0.000409
A32: Gabriel, Gamelyn | B32: 46113 | C32: 7 | D32: 23.8 | E32: 6.4 | F32: 153 | G32: 0.868 | H32: 0.132 | I32: 3 | J32: 0.063 | K32: 48 | L32: 0.0018687 | M32: 0.0016264 | N32: 0.0001329 | O32: 0.0001502 | P32: 0.0001502 | Q32: 105 | R32: 0.0009976 | S32: 0
A33: Gagnon, Nancy | B33: 46113 | C33: 11 | D33: 72 | E33: 7.1 | F33: 509 | G33: 0.693 | H33: 0.307 | I33: 0 | J33: 0 | K33: 108 | L33: 0.0021088 | M33: 0.0019955 | N33: 4.555e-05 | O33: 7.823e-05 | P33: 7.823e-05 | Q33: 400 | R33: 0.0009007 | S33: 1 | T33: 0.0086227
A34: Gil Cervino, Henrique Alexandre | B34: 46113 | C34: 8 | D34: 39.5 | E34: 2.9 | F34: 116 | G34: 0.855 | H34: 0.145 | I34: 1 | J34: 0.04 | K34: 25 | L34: 0.0026699 | M34: 0.0019417 | N34: 0.0003204 | O34: 0.0003838 | P34: 0.0003838 | Q34: 91 | R34: 0.0011143 | S34: 0
A35: Ginete, Maricel | B35: 46113 | C35: 3 | D35: 1.8 | E35: 0.6 | F35: 1 | G35: 0.498 | H35: 0.502 | I35: 0 | K35: 0 | Q35: 1 | R35: 0.000162 | S35: 0
A36: Goddard, Adrien | B36: 46113 | C36: 9 | D36: 55.8 | E36: 15 | F36: 835 | G36: 1 | H36: 0 | I36: 2 | J36: 0.022 | K36: 92 | L36: 0.0025298 | M36: 0.0012393 | N36: 0.0001412 | O36: 0.0003909 | P36: 0.0003909 | Q36: 741 | R36: 0.0010563 | S36: 2 | T36: 0.0001273
A37: Guzman, Alexandre | B37: 46113 | C37: 6 | D37: 49.1 | E37: 11 | F37: 540 | G37: 0.7 | H37: 0.3 | I37: 10 | J37: 0.038 | K37: 266 | L37: 0.002028 | M37: 0.0013063 | N37: 0.000248 | O37: 0.000506 | P37: 0.000506 | Q37: 274 | R37: 0.0009907 | S37: 0
A38: Herbst, Emily Blythe | B38: 46113 | C38: 7 | D38: 51.1 | E38: 12.1 | F38: 619 | G38: 0.336 | H38: 0.664 | I38: 0 | J38: 0 | K38: 33 | L38: 0.001143 | M38: 0.0008631 | N38: 0.0001838 | O38: 0.0002799 | P38: 0.0002799 | Q38: 585 | R38: 0.0009041 | S38: 1 | T38: 0.0006366
A39: Hirst-Smith, Courtnay | B39: 46113 | C39: 9 | D39: 77.6 | E39: 10.9 | F39: 845 | G39: 0.713 | H39: 0.287 | I39: 5 | J39: 0.045 | K39: 112 | L39: 0.0023082 | M39: 0.0013612 | N39: 0.0008231 | O39: 0.0005125 | P39: 0.0005125 | Q39: 733 | R39: 0.0012442 | S39: 0
A40: Hirwa, Jules Adam | B40: 46113 | C40: 5 | D40: 36.3 | E40: 10.5 | F40: 380 | G40: 0.855 | H40: 0.145 | I40: 10 | J40: 0.042 | K40: 236 | L40: 0.002252 | M40: 0.0015495 | N40: 0.0002255 | O40: 0.0004886 | P40: 0.0004886 | Q40: 144 | R40: 0.0009641 | S40: 0
...

Sheet Refined_Data
