Workbook
Name SundayChatNight: Sunday!$B$240:$J$748

Sheet Week Overview
B2: MRC Operation Logbook
B3: Week Starting: | C3: 45844
B4: Versions of IDP | D4: Versions of OT Tracker | H4: Maintenance / Critical Flag | J4: Sunday | K4: Monday | L4: Tuesday | M4: Wednesday | N4: Thursday | O4: Friday | P4: Saturday
B5: IDP Refresh Date | C5: 45842 | D5: OT Refresh Date | H5: Night Shift | J5: =IFERROR(IF(OR(NOT(ISBLANK(Sunday!D211)), NOT(ISBLANK(Sunday!D211))), "!", ""), "") | K5: =IFERROR(IF(OR(NOT(ISBLANK(Monday!D211)), NOT(ISBLANK(Monday!D211))), "!", ""), "") -> ! | L5: =IFERROR(IF(OR(NOT(ISBLANK(Tuesday!D211)), NOT(ISBLANK(Tuesday!D211))), "!", ""), "") -> ! | M5: =IFERROR(IF(OR(NOT(ISBLANK(Wednesday!D211)), NOT(ISBLANK(Wednesday!D211))), "!", ""), "") -> ! | N5: =IFERROR(IF(OR(NOT(ISBLANK(Thursday!D211)), NOT(ISBLANK(Thursday!D211))), "!", ""), "") -> ! | O5: =IFERROR(IF(OR(NOT(ISBLANK(Friday!D211)), NOT(ISBLANK(Friday!D211))), "!", ""), "") -> ! | P5: =IFERROR(IF(OR(NOT(ISBLANK(Saturday!D211)), NOT(ISBLANK(Saturday!D211))), "!", ""), "") -> !
B6: IDP Archive Date 1 | D6: OT Archive Date 1 | H6: Day Shift | J6: =IFERROR(IF(OR(NOT(ISBLANK(Sunday!D755)), NOT(ISBLANK(Sunday!D755))), "!", ""), "") | K6: =IFERROR(IF(OR(NOT(ISBLANK(Monday!D755)), NOT(ISBLANK(Monday!D755))), "!", ""), "") -> ! | L6: =IFERROR(IF(OR(NOT(ISBLANK(Tuesday!D755)), NOT(ISBLANK(Tuesday!D755))), "!", ""), "") -> ! | M6: =IFERROR(IF(OR(NOT(ISBLANK(Wednesday!D755)), NOT(ISBLANK(Wednesday!D755))), "!", ""), "") -> ! | N6: =IFERROR(IF(OR(NOT(ISBLANK(Thursday!D755)), NOT(ISBLANK(Thursday!D755))), "!", ""), "") -> ! | O6: =IFERROR(IF(OR(NOT(ISBLANK(Friday!D755)), NOT(ISBLANK(Friday!D755))), "!", ""), "") -> ! | P6: =IFERROR(IF(OR(NOT(ISBLANK(Saturday!D755)), NOT(ISBLANK(Saturday!D755))), "!", ""), "") -> !
B7: IDP Archive Date 2 | D7: OT Archive Date 2 | H7: Evening Shift | J7: =IFERROR(IF(OR(NOT(ISBLANK(Sunday!D1461)), NOT(ISBLANK(Sunday!D1461))), "!", ""), "") | K7: =IFERROR(IF(OR(NOT(ISBLANK(Monday!D1461)), NOT(ISBLANK(Monday!D1461))), "!", ""), "") -> ! | L7: =IFERROR(IF(OR(NOT(ISBLANK(Tuesday!D1461)), NOT(ISBLANK(Tuesday!D1461))), "!", ""), "") -> ! | M7: =IFERROR(IF(OR(NOT(ISBLANK(Wednesday!D1461)), NOT(ISBLANK(Wednesday!D1461))), "!", ""), "") -> ! | N7: =IFERROR(IF(OR(NOT(ISBLANK(Thursday!D1461)), NOT(ISBLANK(Thursday!D1461))), "!", ""), "") -> ! | O7: =IFERROR(IF(OR(NOT(ISBLANK(Friday!D1461)), NOT(ISBLANK(Friday!D1461))), "!", ""), "") -> ! | P7: =IFERROR(IF(OR(NOT(ISBLANK(Saturday!D1461)), NOT(ISBLANK(Saturday!D1461))), "!", ""), "") -> !
B8: Week Overview
B9: IDP Weekly
G10: Date | H10: Night Shift | K10: Day Shift | N10: Evening Shift
H11: Requirement | I11: Open | J11: Difference | K11: Requirement | L11: Open | M11: Difference | N11: Requirement | O11: Open | P11: Difference
G12: Sunday | H12: =OriginalIDP!H128 -> 15.018571 | I12: =OriginalIDP!I128 -> 20.7375 | J12: =OriginalIDP!J128 -> 5.7189286 | K12: =OriginalIDP!M128 -> 25.785833 | L12: =OriginalIDP!N128 -> 29.619722 | M12: =OriginalIDP!O128 -> 3.8338889 | N12: =OriginalIDP!R128 -> 23.269375 | O12: =OriginalIDP!S128 -> 19.853437 | P12: =OriginalIDP!T128 -> -3.4159375
G13: Monday | H13: =OriginalIDP!H129 -> 16.324643 | I13: =OriginalIDP!I129 -> 17.237857 | J13: =OriginalIDP!J129 -> 0.91321429 | K13: =OriginalIDP!M129 -> 32.311111 | L13: =OriginalIDP!N129 -> 29.453056 | M13: =OriginalIDP!O129 -> -2.8580556 | N13: =OriginalIDP!R129 -> 24.996875 | O13: =OriginalIDP!S129 -> 26.145 | P13: =OriginalIDP!T129 -> 1.148125
G14: Tuesday | H14: =OriginalIDP!H130 -> 15.048214 | I14: =OriginalIDP!I130 -> 20.641786 | J14: =OriginalIDP!J130 -> 5.5935714 | K14: =OriginalIDP!M130 -> 29.666389 | L14: =OriginalIDP!N130 -> 31.777222 | M14: =OriginalIDP!O130 -> 2.1108333 | N14: =OriginalIDP!R130 -> 25.036875 | O14: =OriginalIDP!S130 -> 23.468125 | P14: =OriginalIDP!T130 -> -1.56875
G15: Wednesday | H15: =OriginalIDP!H131 -> 15.734643 | I15: =OriginalIDP!I131 -> 22.285714 | J15: =OriginalIDP!J131 -> 6.5510714 | K15: =OriginalIDP!M131 -> 28.253333 | L15: =OriginalIDP!N131 -> 33.036389 | M15: =OriginalIDP!O131 -> 4.7830556 | N15: =OriginalIDP!R131 -> 24.708437 | O15: =OriginalIDP!S131 -> 26.259687 | P15: =OriginalIDP!T131 -> 1.55125
G16: Thursday | H16: =OriginalIDP!H132 -> 17.158571 | I16: =OriginalIDP!I132 -> 25.035714 | J16: =OriginalIDP!J132 -> 7.8771429 | K16: =OriginalIDP!M132 -> 28.095556 | L16: =OriginalIDP!N132 -> 32.6475 | M16: =OriginalIDP!O132 -> 4.5519444 | N16: =OriginalIDP!R132 -> 24.205625 | O16: =OriginalIDP!S132 -> 27.0825 | P16: =OriginalIDP!T132 -> 2.876875
G17: Friday | H17: =OriginalIDP!H133 -> 18.854286 | I17: =OriginalIDP!I133 -> 22.869286 | J17: =OriginalIDP!J133 -> 4.015 | K17: =OriginalIDP!M133 -> 27.821944 | L17: =OriginalIDP!N133 -> 31.554722 | M17: =OriginalIDP!O133 -> 3.7327778 | N17: =OriginalIDP!R133 -> 24.364375 | O17: =OriginalIDP!S133 -> 26.718125 | P17: =OriginalIDP!T133 -> 2.35375
G18: Saturday | H18: =OriginalIDP!H134 -> 15.457143 | I18: =OriginalIDP!I134 -> 22.761429 | J18: =OriginalIDP!J134 -> 7.3042857 | K18: =OriginalIDP!M134 -> 27.488611 | L18: =OriginalIDP!N134 -> 31.693333 | M18: =OriginalIDP!O134 -> 4.2047222 | N18: =OriginalIDP!R134 -> 22.8875 | O18: =OriginalIDP!S134 -> 22.1975 | P18: =OriginalIDP!T134 -> -0.69
G19: Total | H19: =SUM(H12:H18) -> 113.59607 | I19: =SUM(I12:I18) -> 151.56929 | J19: =SUM(J12:J18) -> 37.973214 | K19: =SUM(K12:K18) -> 199.42278 | L19: =SUM(L12:L18) -> 219.78194 | M19: =SUM(M12:M18) -> 20.359167 | N19: =SUM(N12:N18) -> 169.46906 | O19: =SUM(O12:O18) -> 171.72438 | P19: =SUM(P12:P18) -> 2.2553125
B20: Night Shift Week | G20: Day Shift Week | L20: Evening Shift Week
B32: Weekly Analysis
B33: Compiled Coverage Average | G33: Offline Tasks, Absences & Furlough | M33: IEX Coding Compiled (On Week Completion)
G34: Weekday | H34: Project (hrs) | I34: Furlough(hrs) | J34: Absences Night Shift | K34: Absences Day Shift | L34: Absences Evening Shift | M34: Type And Code | O34: Hours | P34: Total
M35: ACSU Company Solicited Time Off | O35: ='IEX Coding Compiled'!E1 -> 0 | P35: ='IEX Coding Compiled'!E1 -> 0
G36: Sunday | H36: =(SUM(Sunday!D234 + Sunday!D778 + Sunday!D1484)) -> 0 | I36: =SUM(Sunday!D1481 + Sunday!D775 + Sunday!D231) -> 0 | J36: =SUM(Sunday!C231 + Sunday!C232) -> 0 | K36: =SUM(Sunday!C775 + Sunday!C776) -> 0 | L36: =SUM(Sunday!C1481 + Sunday!C1482) -> 0 | M36: CE-HUDDLE | O36: ='IEX Coding Compiled'!J1 -> 0 | P36: =SUM('IEX Coding Compiled'!Y1,'IEX Coding Compiled'!O1,'IEX Coding Compiled'!J1,'IEX Coding Compiled'!AS1) -> 0
G37: Monday | H37: =(SUM(Monday!D234 + Monday!D778 + Monday!D1484)) -> #REF! | I37: =SUM(Monday!D1481 + Monday!D775 + Monday!D231) -> #REF! | J37: =SUM(Monday!C231 + Monday!C232) -> #REF! | K37: =SUM(Monday!C775 + Monday!C776) -> #REF! | L37: =SUM(Monday!C1481 + Monday!C1482) -> #REF! | M37: DEV Development | O37: ='IEX Coding Compiled'!O1 -> 0
G38: Tuesday | H38: =(SUM(Tuesday!D234 + Tuesday!D778 + Tuesday!D1484)) -> #REF! | I38: =SUM(Tuesday!D1481 + Tuesday!D775 + Tuesday!D231) -> #REF! | J38: =SUM(Tuesday!C231 + Tuesday!C232) -> #REF! | K38: =SUM(Tuesday!C775 + Tuesday!C776) -> #REF! | L38: =SUM(Tuesday!C1481 + Tuesday!C1482) -> #REF! | M38: ONE Meeting: One on One | O38: ='IEX Coding Compiled'!Y1 -> 0
G39: Wednesday | H39: =(SUM(Wednesday!D234 + Wednesday!D778 + Wednesday!D1484)) -> #REF! | I39: =SUM(Wednesday!D1481 + Wednesday!D775 + Wednesday!D231) -> #REF! | J39: =SUM(Wednesday!C231 + Wednesday!C232) -> #REF! | K39: =SUM(Wednesday!C775 + Wednesday!C776) -> #REF! | L39: =SUM(Wednesday!C1481 + Wednesday!C1482) -> #REF! | M39: SBYS SidexSide Coaching | O39: ='IEX Coding Compiled'!AS1 -> 0
G40: Thursday | H40: =(SUM(Thursday!D234 + Thursday!D778 + Thursday!D1484)) -> #REF! | I40: =SUM(Thursday!D1481 + Thursday!D775 + Thursday!D231) -> #REF! | J40: =SUM(Thursday!C231 + Thursday!C232) -> #REF! | K40: =SUM(Thursday!C775 + Thursday!C776) -> #REF! | L40: =SUM(Thursday!C1481 + Thursday!C1482) -> #REF! | M40: READ | O40: ='IEX Coding Compiled'!AD1 -> 0 | P40: =Sum(O40,O41,O42,O43) -> 0
G41: Friday | H41: =(SUM(Friday!D234 + Friday!D778 + Friday!D1484)) -> #REF! | I41: =SUM(Friday!D1481 + Friday!D775 + Friday!D231) -> #REF! | J41: =SUM(Friday!C231 + Friday!C232) -> #REF! | K41: =SUM(Friday!C775 + Friday!C776) -> #REF! | L41: =SUM(Friday!C1481 + Friday!C1482) -> #REF! | M41: LFQI On Loan, OffQ, OPEX | O41: ='IEX Coding Compiled'!T1 -> 0
G42: Saturday | H42: =(SUM(Saturday!D234 + Saturday!D778 + Saturday!D1484)) -> #REF! | I42: =SUM(Saturday!D1481 + Saturday!D775 + Saturday!D231) -> #REF! | J42: =SUM(Saturday!C231 + Saturday!C232) -> #REF! | K42: =SUM(Saturday!C775 + Saturday!C776) -> #REF! | L42: =SUM(Saturday!C1481 + Saturday!C1482) -> #REF! | M42: WOFQT Team Lead Ofq Work | O42: ='IEX Coding Compiled'!AN1 -> 0
G43: Total | H43: =SUM(H36:H42) -> #REF! | I43: =SUM(I36:I42) -> #REF! | J43: =SUM(J36:J42) -> #REF! | K43: =SUM(K36:K42) -> #REF! | L43: =SUM(L36:L42) -> #REF! | M43: TRN1 OffQ - eLearnings | O43: ='IEX Coding Compiled'!AI1 -> 0
B44: Alarms Data (On Week Completion) | H44: Calls Data (On Week Completion) | N44: Coaching + Offtasks Total | P44: =Sum(P36,P40) -> 0
N45: Misc.
B46: Alarms Offered | C46: 0 | D46: Prev. A.Offered | E46: 0 | F46: WoW Off. Dif. | G46: =(C46 - E46) -> 0 | H46: Calls Offered | I46: 0 | J46: Prev. C.Offered | K46: 0 | L46: WoW Off. Dif. | M46: =(I46 - K46) -> 0 | N46: CLASSROOM | P46: ='IEX Coding Compiled'!AX1 -> 0
B47: Alarms Forecast | C47: 0 | D47: Prev A. Forecast | E47: 0 | F47: WoW For. Dif. | G47: =(C47 - E47) -> 0 | H47: Calls Forecast | I47: 0 | J47: Prev C Forecast | K47: 0 | L47: WoW For. Dif. | M47: =(I47 - K47) -> 0 | N47: MEET Dir / Roadshows | P47: ='IEX Coding Compiled'!BC1 -> 0
B48: Alarms Dif % | C48: 0 | D48: Prev A. Dif. % | E48: 0 | F48: WoW A. Dif % | G48: =(C48 - E48) -> 0 | H48: Calls Dif % | I48: 0 | J48: Prev C. Dif. % | K48: 0 | L48: WoW C. Dif % | M48: =(I48 - K48) -> 0 | N48: AUTH Authorized time off | P48: ='IEX Coding Compiled'!BH1 -> 0
B49: Volume vs Forecast | G49: Weekday Offered vs Forecasted
G50: Weekday | H50: Alarms Offered | I50: Alarms Frcst | J50: % Difference | K50: Calls Offered | L50: Calls Forecast | M50: % Difference
G52: Sunday | H52: =Sunday!P6 | I52: =Sunday!P7 | J52: =((H52-I52)/I52) -> #DIV/0! | K52: =Sunday!P10 | L52: =Sunday!P11 | M52: =((K52-L52)/L52) -> #DIV/0!
G53: Monday | H53: =Monday!P6 -> #REF! | I53: =Monday!P7 -> #REF! | J53: =((H53-I53)/I53) -> #REF! | K53: =Monday!P10 -> #REF! | L53: =Monday!P11 -> #REF! | M53: =((K53-L53)/L53) -> #REF!
...

Sheet Stats History
A1: Timestamp | B1: SVL | C1: ACK
A2: 46018.291 | B2: 0 | C2: 0
A3: 46018.293 | B3: 84 | C3: 38
A4: 46018.317 | B4: 85 | C4: 36
A5: 46018.319 | B5: 94 | C5: 27
A6: 46018.319 | B6: 94 | C6: 27
A7: 46018.321 | B7: 94 | C7: 30
A8: 46018.322 | B8: 94 | C8: 30
A9: 46018.322 | B9: 94 | C9: 30
A10: 46018.324 | B10: 94 | C10: 30
A11: 46018.326 | B11: 94 | C11: 30
A12: 46018.33 | B12: 90 | C12: 30
A13: 46020.071 | B13: 96 | C13: 2
... A15: 46021.064 | B15: 95 | C15: 7

Sheet Status_Overrides
A1: Timestamp | B1: Agent Name | C1: Role | D1: Absent Type | E1: DateStr
A2: 46018.272 | B2: Lawrence Wong | C2: SAFE | E2: 46018
A3: 46019.217 | B3: Myriam Ouchchane | E3: 46019
A4: 46019.217 | B4: Jessica Popovic | C4: SAFE | E4: 46019
A5: 46019.244 | B5: Manpreet Kaur | C5: SAFE | E5: 46019
A6: 46019.244 | B6: Mohamed El Ghanjawi | C6: ICL | E6: 46019
A7: 46019.244 | B7: Oussama Ouahbi | C7: ICL | E7: 46019
A8: 46019.244 | B8: Abdelmalek Aboul-Hilal | C8: ICL | E8: 46019
A9: 46020.174 | B9: Lawrence Wong | C9: SAFE | E9: 46020
A10: 46020.174 | B10: Jessica Popovic | E10: 46020
A11: 46021.047 | B11: Oussama Ouahbi | C11: ICL | E11: 46021
A12: 46021.05 | B12: Hicham Boutzila | C12: ICL | E12: 46021
A13: 46021.166 | B13: Jessica Popovic | C13: SAFE | E13: 46021
A14: 46029.976 | B14: Carl Carrel Gatore | C14: SAFE | E14: 46029
A15: 46029.976 | B15: Ismail Balla | C15: ICL | E15: 46029
A16: 46030.005 | B16: Carl Carrel Gatore | C16: SAFE | E16: 46030
A17: 46030.006 | B17: Lawrence Wong | C17: SAFE | E17: 46030
A18: 46030.013 | B18: Ismail Balla | C18: Active | E18: 46030
A19: 46030.013 | B19: Abdelmalek Aboul-Hilal | C19: ICL | E19: 46030
A20: 46030.014 | B20: Ilham Elfarik | C20: ICL | E20: 46030
A21: 46030.014 | B21: Jessica Popovic | C21: Active | E21: 46030
A22: 46030.059 | B22: Oussama Ouahbi | C22: ICL | E22: 46030
A23: 46030.067 | B23: Vida Rennie | D23: SICK | E23: 46030

Sheet Team_Scripts
A1: Title | B1: Script Body | C1: Category
A2: Long Call Check | B2: Hi, I noticed you've been on this call for 15+ mins. Do you need supervisor assistance? | C2: Agent Check
A3: Late from Break | B3: Hi, checking in—you're showing as away past your break time. Everything good? | C3: Agent Check
A4: ACW Nudge | B4: Hi, quick check-in on your ACW status. Need any help? | C4: Agent Check
A5: Increased BURG alarms | B5: Hi / Salut @all agents working on outbound☺️ We're seeing an increase in BURG alarms, when you have a moment can you let me know if there are any specific or unusual causes for those alarms please? Nous constatons maintenant une augmentation des alarmes de CAMBRIOLAGE, lorsque vous avez un moment, pouvez-vous me faire savoir s'il existe des causes spécifiques ou inhabituelles pour ces alarmes svp?
A6: Increased INBOUND alarms | B6: Hi / Salut INBOUND agents We've been seeing an increase of inbound call for the past 60 minutes, when you have a moment can you let me know if there are any pattern, specific or unusual causes for the alarms that you've been getting please? If you've noticed more of the following, you can just react with: For tech calls use 🪛 for Weather use 🌬️ Client mistake or recent arm / close alarms with a 🤦 Related to internet or IC-COMM with a 🛜 No clear reason with a 🦄 Nous avons constaté une augmentation des appels entrant au cours des 60 dernières minutes, lorsque vous avez un moment, pouvez-vous me faire savoir s'il existe des causes spécifiques ou inhabituelles pour les alarmes que vous recevez svp? Si vous avez remarqués plus d'alarmes reliés à ceux-ci, svp répondez avec le émoji qui le représente: Relié a la température avec un 🌬️ Erreur client avec un 🤦 Relié à un IC-COMM ou problème internet avec un 🛜 Sans raison spécifique avec un 🦄 Merci encore de votre excellent travail 🙂
A7: Friendly Reminder // Rappel Amicale (Power failure) | B7: Due to the numerous power outages, if you contact customers regarding this situation, I recommend: Propose, with their agreement, to temporarily put on test the management of power outage-related alarm signals: 4-COMM, 5-SUPF, 7-TRB, 7-TRCF, 8-TPWR, 9-BATT. Set a specific duration for this measure with the customer. This will prevent additional work for us. Thank you 😊 _______________________________________________________________________________ En raison des nombreuses pannes de courant, si vous contactez des clients à ce sujet, je recommande de : Proposer, avec leur accord, de temporairement mettre en test les signaux liés aux pannes : 4-COMM, 5-SUPF, 7-TRB, 7-TRCF, 8-TPWR, 9-BATT. Fixer une durée précise pour cette mesure avec le client. Cela nous évitera du travail supplémentaire. Merci 😊
A8: WINTER strategy | B8: 🎄 STAFFING 🎄 _____ our staffing conditions are _____ On-shore: Planned / Unplanned absences Off-shore: 0 Planned / 0 Unplanned absence ❄️ WEATHER ❄️ There is no scheduled maintenance for today — smooth sleigh rides ahead. 🎁 FOCUS 🎁 🔥LS ULC: We will have agent 📠 ICL: We will rely on offshore agents to run the ICL. 🛟 Life Safety: We will assign LS agents offshore 🛡️ SAFE: We will assign agents who will be set to FIRE ULC ALARM only. | C8: Strategy
A9: Outbound High volume | B9: Hi / Salut @all OUTBOUND agents We've been seeing an increase in Burglary Alarms (BA) for the past 60 minutes, when you have a moment can you let me know if there are any pattern, specific or unusual causes for the alarms that you've been getting please? If you've noticed more of the following, please respond with the following emoji: If related to wind, respond with🍃 If related to rain or snow, respond with ❄️ If related to a customer mistake, please respond with🎅 Related to internet or IC-COMM with a 🛜 No clear reason with a 🤷🏼‍♂️ Thanks as always for your hard work 🙂 Nous avons constaté une augmentation des alarmes D'intrustions (BA) au cours des 60 dernières minutes, lorsque vous avez un moment, pouvez-vous me faire savoir s'il existe des causes spécifiques ou inhabituelles pour les alarmes que vous recevez svp? Si vous avez remarqués plus d'alarmes reliés à ceux-ci, svp répondez avec le émoji qui le représente: Relié au vent, répondez avec un 🍃 Relié à la neige ou pluie avec un ❄️ Erreur client avec un🎅 Relié à un IC-COMM ou problème internet avec un 🛜 Sans raison spécifique avec un 🤷🏼‍♂️ Merci encore de votre excellent travail 🙂 | C9: General

Sheet System_Notifications
A1: ID | B1: Timestamp | C1: Message | D1: Status | E1: AgentName
A2: 1765525709024 | B2: 46003.117 | C2: Code Emily Ratz as SAFE in IEX | D2: DONE | E2: Emily Ratz
A3: 1765525716039 | B3: 46003.117 | C3: Code Carl Carrel Gatore as SAFE in IEX | D3: DONE | E3: Carl Carrel Gatore
A4: 1765525720582 | B4: 46003.117 | C4: Code Sheila Kenol as SAFE in IEX | D4: DONE | E4: Sheila Kenol
A5: 1765530956449 | B5: 46003.177 | C5: Code Lawrence Wong as SAFE in IEX | D5: DONE | E5: Lawrence Wong
A6: 1765605562837 | B6: 46004.041 | C6: Code Hajar Akherraz as SAFE in IEX | D6: DONE | E6: Hajar Akherraz
A7: 1765605566659 | B7: 46004.041 | C7: Code Hajar Akherraz as Active in IEX | D7: DONE | E7: Hajar Akherraz
A8: 1765605574366 | B8: 46004.041 | C8: Code Myriam Ouchchane as SAFE in IEX | D8: DONE | E8: Myriam Ouchchane
A9: 1765605580687 | B9: 46004.041 | C9: Code Andre Masiero as SAFE in IEX | D9: DONE | E9: Andre Masiero
A10: 1765606930125 | B10: 46004.057 | C10: Code Abdelmalek Aboul-Hilal as ICL in IEX | D10: DONE | E10: Abdelmalek Aboul-Hilal
A11: 1765631985914 | B11: 46004.347 | C11: Code Imad Alati as Breaks Modified in IEX | D11: DONE | E11: Imad Alati
A12: 1765632635452 | B12: 46004.354 | C12: Code Imad Alati as Breaks Modified in IEX | D12: DONE | E12: Imad Alati
A13: 1765632656810 | B13: 46004.354 | C13: Code Imad Alati as Breaks Modified in IEX | D13: DONE | E13: Imad Alati
... A25: 1765979928934 | B25: 46008.374 | C25: Code Diego Armando Carvajal Yiptong as Active in IEX | D25: DONE | E25: Diego Armando Carvajal Yiptong

Sheet Raw Schedule
A1: Agent Name | B1: ID | C1: DateStr | D1: Shift Start | E1: Shift End | F1: Shift Type | G1: Region | H1: Breaks JSON | I1: Role | J1: AbsentType | K1: StartEpoch | L1: EndEpoch
A2: Hamza Aazzaz | B2: 326333 | C2: 46029 | F2: Off | G2: Onshore | H2: []
A3: Hamza Aazzaz | B3: 326333 | C3: 46030 | F3: Off | G3: Onshore | H3: []
A4: Mohammed Abouda | B4: 773560 | C4: 46029 | F4: Off | G4: Onshore | H4: []
A5: Mohammed Abouda | B5: 773560 | C5: 46030 | D5: 0.27083333 | E5: 0.70833333 | F5: Day | G5: Onshore | H5: [{"type":"Break","start":"8:20 AM","end":"8:30 AM"},{"type":"Break","start":"10:50 AM","end":"11:00 AM"},{"type":"Lunch","start":"1:00 PM","end":"1:30 PM"},{"type":"Break","start":"3:20 PM","end":"3:30 PM"}] | K5: 1767871800000 | L5: 1767909600000
A6: Abdelmalek Aboul-Hilal | B6: 321378 | C6: 46029 | D6: 0.98958333 | E6: 0.36458333 | F6: Evening | G6: Offshore | H6: [{"type":"Break","start":"2:00 AM","end":"2:15 AM"},{"type":"Lunch","start":"4:00 AM","end":"5:00 AM"},{"type":"Break","start":"6:45 AM","end":"7:00 AM"}] | K6: 1767847500000 | L6: 1767879900000
A7: Abdelmalek Aboul-Hilal | B7: 321378 | C7: 46030 | D7: 0.98958333 | E7: 0.36458333 | F7: Evening | G7: Offshore | H7: [{"type":"Break","start":"2:00 AM","end":"2:15 AM"},{"type":"Lunch","start":"4:00 AM","end":"5:00 AM"},{"type":"Break","start":"6:30 AM","end":"6:45 AM"}] | K7: 1767933900000 | L7: 1767966300000
A8: Salah-eddine Adib | B8: 330867 | C8: 46029 | D8: 0.875 | E8: 0.25 | F8: Evening | G8: Offshore | H8: [{"type":"Lunch","start":"1:00 AM","end":"2:00 AM"}] | J8: NCNS | K8: 1767837600000 | L8: 1767870000000
A9: Salah-eddine Adib | B9: 330867 | C9: 46030 | D9: 0.875 | E9: 0.25 | F9: Evening | G9: Offshore | H9: [{"type":"Break","start":"11:00 PM","end":"11:15 PM"},{"type":"Lunch","start":"1:00 AM","end":"2:00 AM"},{"type":"Break","start":"3:30 AM","end":"3:45 AM"}] | K9: 1767924000000 | L9: 1767956400000
A10: Othmane Ahmar Lahya | B10: 325808 | C10: 46029 | D10: 0.67708333 | E10: 0.052083333 | F10: Evening | G10: Offshore | H10: [{"type":"Break","start":"6:00 PM","end":"6:15 PM"},{"type":"Lunch","start":"7:45 PM","end":"8:45 PM"},{"type":"Break","start":"10:30 PM","end":"10:45 PM"}] | K10: 1767820500000 | L10: 1767852900000
A11: Othmane Ahmar Lahya | B11: 325808 | C11: 46030 | D11: 0.67708333 | E11: 0.052083333 | F11: Evening | G11: Offshore | H11: [{"type":"Break","start":"6:00 PM","end":"6:15 PM"},{"type":"Lunch","start":"7:45 PM","end":"8:45 PM"},{"type":"Break","start":"10:30 PM","end":"10:45 PM"}] | K11: 1767906900000 | L11: 1767939300000
A12: Nabil Aidoud | B12: 955715 | C12: 46029 | F12: Off | G12: Onshore | H12: []
A13: Nabil Aidoud | B13: 955715 | C13: 46030 | D13: 0.35416667 | E13: 0.77083333 | F13: Day | G13: Onshore | H13: [{"type":"Break","start":"10:50 AM","end":"11:00 AM"},{"type":"Break","start":"12:30 PM","end":"12:40 PM"},{"type":"Break","start":"4:55 PM","end":"5:05 PM"}] | K13: 1767879000000 | L13: 1767915000000
A14: Kawtar Ajdaa | B14: 358028 | C14: 46029 | D14: 0.73958333 | E14: 0.11458333 | F14: Evening | G14: Offshore | H14: [{"type":"Break","start":"8:15 PM","end":"8:30 PM"},{"type":"Lunch","start":"10:00 PM","end":"11:00 PM"},{"type":"Break","start":"12:45 AM","end":"1:00 AM"}] | K14: 1767825900000 | L14: 1767858300000
A15: Kawtar Ajdaa | B15: 358028 | C15: 46030 | D15: 0.73958333 | E15: 0.11458333 | F15: Evening | G15: Offshore | H15: [{"type":"Break","start":"8:00 PM","end":"8:15 PM"},{"type":"Lunch","start":"9:45 PM","end":"10:45 PM"},{"type":"Break","start":"12:45 AM","end":"1:00 AM"}] | K15: 1767912300000 | L15: 1767944700000
A16: Hajar Akherraz | B16: 996872 | C16: 46029 | F16: Off | G16: Onshore | H16: []
A17: Hajar Akherraz | B17: 996872 | C17: 46030 | D17: 0.89583333 | E17: 0.27083333 | F17: Evening | G17: Onshore | H17: [{"type":"Break","start":"11:30 PM","end":"11:45 PM"},{"type":"Lunch","start":"2:00 AM","end":"2:30 AM"},{"type":"Break","start":"4:15 AM","end":"4:30 AM"}] | K17: 1767925800000 | L17: 1767958200000
A18: Imad Alati | B18: 374349 | C18: 46029 | D18: 0.16666667 | E18: 0.16666667 | F18: Day | G18: Offshore | H18: [] | J18: SICK | K18: 1767776400000 | L18: 1767776400000
A19: Imad Alati | B19: 374349 | C19: 46030 | F19: Off | G19: Onshore | H19: []
A20: Marouane Anniba | B20: 359012 | C20: 46029 | D20: 0.375 | E20: 0.70833333 | F20: Day | G20: Offshore | H20: [{"type":"Break","start":"10:45 AM","end":"11:00 AM"},{"type":"Lunch","start":"12:30 PM","end":"1:00 PM"},{"type":"Break","start":"3:15 PM","end":"3:30 PM"}] | J20: TRAINING | K20: 1767794400000 | L20: 1767823200000
A21: Marouane Anniba | B21: 359012 | C21: 46030 | D21: 0.375 | E21: 0.70833333 | F21: Day | G21: Offshore | H21: [{"type":"Break","start":"10:45 AM","end":"11:00 AM"},{"type":"Lunch","start":"12:30 PM","end":"1:00 PM"},{"type":"Break","start":"3:15 PM","end":"3:30 PM"}] | J21: TRAINING | K21: 1767880800000 | L21: 1767909600000
A22: Mohamed Anounou | B22: 325788 | C22: 46029 | D22: 0.36458333 | E22: 0.73958333 | F22: Day | G22: Offshore | H22: [{"type":"Break","start":"10:30 AM","end":"10:45 AM"},{"type":"Lunch","start":"12:30 PM","end":"1:30 PM"},{"type":"Break","start":"3:00 PM","end":"3:15 PM"}] | K22: 1767793500000 | L22: 1767825900000
A23: Mohamed Anounou | B23: 325788 | C23: 46030 | D23: 0.36458333 | E23: 0.73958333 | F23: Day | G23: Offshore | H23: [{"type":"Break","start":"10:45 AM","end":"11:00 AM"},{"type":"Lunch","start":"12:15 PM","end":"1:15 PM"},{"type":"Break","start":"3:00 PM","end":"3:15 PM"}] | K23: 1767879900000 | L23: 1767912300000
A24: Lester Aquilario | B24: 988376 | C24: 46029 | D24: 0.4375 | E24: 0.8125 | F24: Day | G24: Onshore | H24: [] | K24: 1767799800000 | L24: 1767832200000
A25: Lester Aquilario | B25: 988376 | C25: 46030 | D25: 0.4375 | E25: 0.8125 | F25: Day | G25: Onshore | H25: [{"type":"Break","start":"12:15 PM","end":"12:30 PM"},{"type":"Lunch","start":"3:00 PM","end":"3:30 PM"},{"type":"Break","start":"5:30 PM","end":"5:45 PM"},{"type":"Break","start":"1:00 PM","end":"1:15 PM"},{"type":"Lunch","start":"3:00 PM","end":"3:30 PM"},{"type":"Break","start":"5:30 PM","end":"5:45 PM"}] | K25: 1767886200000 | L25: 1767918600000
A26: Dominic Audet | B26: 996384 | C26: 46029 | D26: 0.72916667 | E26: 0.083333333 | F26: Evening | G26: Onshore | H26: [{"type":"Break","start":"7:30 PM","end":"7:45 PM"},{"type":"Break","start":"12:00 AM","end":"12:15 AM"}] | K26: 1767825000000 | L26: 1767855600000
A27: Dominic Audet | B27: 996384 | C27: 46030 | F27: Off | G27: Onshore | H27: []
A28: Adrien Auger | B28: 973054 | C28: 46029 | D28: 0.73958333 | E28: 0.17708333 | F28: Evening | G28: Onshore | H28: [{"type":"Break","start":"7:45 PM","end":"7:55 PM"},{"type":"Break","start":"9:45 PM","end":"9:55 PM"},{"type":"Lunch","start":"11:45 PM","end":"12:15 AM"},{"type":"Break","start":"2:20 AM","end":"2:30 AM"}] | K28: 1767825900000 | L28: 1767863700000
A29: Adrien Auger | B29: 973054 | C29: 46030 | F29: Off | G29: Onshore | H29: []
A30: Jean-Gabriel Baisi | B30: 773726 | C30: 46029 | D30: 0.375 | E30: 0.8125 | F30: Day | G30: Onshore | H30: [{"type":"Break","start":"11:30 AM","end":"11:40 AM"},{"type":"Break","start":"1:30 PM","end":"1:40 PM"},{"type":"Lunch","start":"3:15 PM","end":"3:45 PM"},{"type":"Break","start":"5:25 PM","end":"5:35 PM"}] | K30: 1767794400000 | L30: 1767832200000
A31: Jean-Gabriel Baisi | B31: 773726 | C31: 46030 | F31: Off | G31: Onshore | H31: []
A32: Ismail Balla | B32: 321377 | C32: 46029 | D32: 0.625 | E32: 0 | F32: Evening | G32: Offshore | H32: [{"type":"Break","start":"5:15 PM","end":"5:30 PM"},{"type":"Lunch","start":"7:15 PM","end":"8:15 PM"},{"type":"Break","start":"9:45 PM","end":"10:00 PM"}] | K32: 1767816000000 | L32: 1767848400000
A33: Ismail Balla | B33: 321377 | C33: 46030 | D33: 0.625 | E33: 0 | F33: Evening | G33: Offshore | H33: [{"type":"Break","start":"5:15 PM","end":"5:30 PM"},{"type":"Lunch","start":"7:15 PM","end":"8:15 PM"},{"type":"Break","start":"9:45 PM","end":"10:00 PM"}] | K33: 1767902400000 | L33: 1767934800000
A34: Soufiane Bari | B34: 385485 | C34: 46029 | D34: 0.97916667 | E34: 0.35416667 | F34: Evening | G34: Offshore | H34: [{"type":"Break","start":"1:45 AM","end":"2:00 AM"},{"type":"Lunch","start":"3:30 AM","end":"4:30 AM"},{"type":"Break","start":"6:30 AM","end":"6:45 AM"}] | K34: 1767846600000 | L34: 1767879000000
A35: Soufiane Bari | B35: 385485 | C35: 46030 | F35: Off | G35: Onshore | H35: []
A36: Anass Barrodi | B36: 323620 | C36: 46029 | D36: 0.71875 | E36: 0.09375 | F36: Evening | G36: Offshore | H36: [{"type":"Break","start":"7:00 PM","end":"7:15 PM"},{"type":"Lunch","start":"9:15 PM","end":"10:15 PM"},{"type":"Break","start":"12:00 AM","end":"12:15 AM"}] | K36: 1767824100000 | L36: 1767856500000
A37: Anass Barrodi | B37: 323620 | C37: 46030 | D37: 0.71875 | E37: 0.09375 | F37: Evening | G37: Offshore | H37: [{"type":"Break","start":"7:00 PM","end":"7:15 PM"},{"type":"Lunch","start":"9:15 PM","end":"10:15 PM"},{"type":"Break","start":"12:00 AM","end":"12:15 AM"}] | K37: 1767910500000 | L37: 1767942900000
A38: Mohamed Behate | B38: 323447 | C38: 46029 | D38: 0.44791667 | E38: 0.82291667 | F38: Day | G38: Offshore | H38: [{"type":"Break","start":"12:40 PM","end":"12:55 PM"},{"type":"Lunch","start":"2:45 PM","end":"3:45 PM"},{"type":"Break","start":"5:15 PM","end":"5:30 PM"}] | J38: NCNS | K38: 1767800700000 | L38: 1767833100000
A39: Mohamed Behate | B39: 323447 | C39: 46030 | D39: 0.44791667 | E39: 0.82291667 | F39: Day | G39: Onshore | H39: [] | K39: 1767887100000 | L39: 1767919500000
A40: Safae Benmouna | B40: 385480 | C40: 46029 | D40: 0.6875 | E40: 0.0625 | F40: Evening | G40: Offshore | H40: [{"type":"Break","start":"6:30 PM","end":"6:45 PM"},{"type":"Lunch","start":"8:15 PM","end":"9:15 PM"},{"type":"Break","start":"11:00 PM","end":"11:15 PM"}] | K40: 1767821400000 | L40: 1767853800000
...

Sheet DB_Volume
A1: Date | B1: Time | C1: Inbound | D1: Outbound | E1: Trend_In | F1: Trend_Out

Sheet DB_WeekStats
A1: Day | B1: Shift | C1: Requirement | D1: Open | E1: Difference

Sheet Sunday
F1: . | G1: . | H1: .
B2: Sunday | E2: ='Week Overview'!C3 -> 45844 | F2: . | G2: . | H2: .
F3: . | G3: . | H3: .
B4: Intraday Service Level Log | G4: Weather Report | O4: Complete Day Data
G5: Key Locations | I5: Wind Night | J5: Wind Day | K5: Wind Even | L5: Notes
G6: Toronto | O6: Alarms Offrd
G7: Ottawa | O7: Alarms Frcst
G8: Calgary | O8: ACK
G9: Edmonton | O9: LAW
G10: Vancouver | O10: Calls Offrd
G11: Prince George | O11: Calls Frcst
G12: Montreal | O12: ASA
G13: Quebec | O13: LCW
B14: Trend Expended | G14: IDP Expanded
B16: Weather Report
B17: Weather Report
I27: MSN Weather login : telusmrc@hotmail.com Pw: mrc68888
B206: Night Shift
B207: NIGHT SHIFT | C207: Daily Resume | G207: IDP Overview | M207: Trend
C208: MRC and Bckup
C209: Weather Alert
C210: Maintenance
C211: Critical Event(s) / Crashes / Anything out of the Ordinary
G221: Coverage
H222: Agent Ability | I222: 0 | J222: 0.041666667 | K222: 0.083333333 | L222: 0.125 | M222: 0.16666667 | N222: 0.20833333 | O222: 0.25
G223: Doesn't take | H223: Inbound French | I223: =CoverageReport!D2 -> 16 | J223: =CoverageReport!E2 -> 16 | K223: =CoverageReport!F2 -> 17 | L223: =CoverageReport!G2 -> 16 | M223: =CoverageReport!H2 -> 17 | N223: =CoverageReport!I2 -> 19 | O223: =CoverageReport!J2 -> 25
G224: into consideration | H224: Inbound English | I224: =CoverageReport!D3 -> 16 | J224: =CoverageReport!E3 -> 18 | K224: =CoverageReport!F3 -> 20 | L224: =CoverageReport!G3 -> 18 | M224: =CoverageReport!H3 -> 17 | N224: =CoverageReport!I3 -> 18 | O224: =CoverageReport!J3 -> 23
G225: - Unplanned Abs. | H225: ULC French | I225: =CoverageReport!D4 -> 13 | J225: =CoverageReport!E4 -> 12 | K225: =CoverageReport!F4 -> 10 | L225: =CoverageReport!G4 -> 9 | M225: =CoverageReport!H4 -> 9 | N225: =CoverageReport!I4 -> 10 | O225: =CoverageReport!J4 -> 13
G226: - Breaks & Lunch | H226: ULC English | I226: =CoverageReport!D5 -> 14 | J226: =CoverageReport!E5 -> 15 | K226: =CoverageReport!F5 -> 14 | L226: =CoverageReport!G5 -> 12 | M226: =CoverageReport!H5 -> 10 | N226: =CoverageReport!I5 -> 9 | O226: =CoverageReport!J5 -> 11
G227: - Last minute coding | H227: SAFE | I227: =CoverageReport!D6 -> 8 | J227: =CoverageReport!E6 -> 9 | K227: =CoverageReport!F6 -> 9 | L227: =CoverageReport!G6 -> 9 | M227: =CoverageReport!H6 -> 8 | N227: =CoverageReport!I6 -> 6 | O227: =CoverageReport!J6 -> 7
H228: Expert | I228: =CoverageReport!D7 -> 7 | J228: =CoverageReport!E7 -> 7 | K228: =CoverageReport!F7 -> 7 | L228: =CoverageReport!G7 -> 7 | M228: =CoverageReport!H7 -> 5 | N228: =CoverageReport!I7 -> 4 | O228: =CoverageReport!J7 -> 5
B230: Absences | D230: Furl.(Hrs) | E230: Stats Update: | G230: LAWs | L230: Service Level
B231: Planned | D231: 0 | E231: 23h00 - 00h00 | F231: =SundayBin!AH3 -> Missing
B232: Unplanned | E232: 01h00 | F232: =SundayBin!AH4 -> Missing
B233: Staffing | D233: Project (Hrs) | E233: 02h00 | F233: =SundayBin!AH5 -> Missing
B234: 00h00-02h00 | C234: =SundayBin!AB2 -> 21.41625 | D234: 0 | E234: 03h00 | F234: =SundayBin!AH6 -> Missing
B235: 02h00-04h00 | C235: =SundayBin!AB3 -> 19.415 | D235: Expanded Notes ? | E235: 04h00 | F235: =SundayBin!AH7 -> Missing
B236: 04h00-06h00 | C236: =SundayBin!AB4 -> 18.741111 | D236: Yes / No | E236: 05h00 | F236: =SundayBin!AH8 -> Missing
B237: 06h00-08h00 | C237: =SundayBin!AB5 -> 27.516667 | E237: 06h00 | F237: =SundayBin!AH9 -> Missing
B239: VVV UNHIDE FOR CHAT LOGS ( USE STAR ICON TO REHIDE ) VVV
...

Sheet DB_Templates
A1: Title | B1: Body
A2: Example Template | B2: This is an example.

Sheet SundayBin
F1: Stats Update ~ 23h00 - 00h00 | K1: Stats Update ~ 07h00 - 08h00 | P1: Stats Update ~ 15h00 - 16h00 | W1: 0 | X1: =OriginalIDP!C3 -> 16.43 | Y1: =OriginalIDP!D3 -> 19 | Z1: =OriginalIDP!E3 -> 2.57 | AC1: 0 | AD1: 0 | AE1: 0 | AH1: 0 | AI1: 0
F2: ACK | G2: =J5 | J2: =IFERROR(__xludf.DUMMYFUNCTION("REGEXREPLACE(I2,""(.*)ACK:(.*)"",""$2"")"),"") | K2: ACK | L2: =O5 | O2: =IFERROR(__xludf.DUMMYFUNCTION("REGEXREPLACE(N2,""(.*)ACK:(.*)"",""$2"")"),"") | P2: ACK | Q2: =T5 | T2: =IFERROR(__xludf.DUMMYFUNCTION("REGEXREPLACE(S2,""(.*)ACK:(.*)"",""$2"")"),"") | W2: 0.010416667 | X2: =OriginalIDP!C4 -> 16.77 | Y2: =OriginalIDP!D4 -> 19.33 | Z2: =OriginalIDP!E4 -> 2.56 | AA2: 00h00-02h00 | AB2: =AVERAGE(Y1:Y8) -> 21.41625 | AC2: Time | AD2: Outbound | AE2: Inbound | AF2: Inbound Trend | AG2: Outbound Trend | AI2: Time | AJ2: Outbound | AK2: Inbound | AL2: Inbound Trend | AM2: Outbound Trend | AN2: LAW Lifesafety | AO2: LAW Burglary
F3: ASA | G3: =J6 | J3: =IFERROR(__xludf.DUMMYFUNCTION("REGEXREPLACE(I3,""(.*)SVL OUT:(.*)"",""$2"")"),"") | K3: ASA | L3: =O6 | O3: =IFERROR(__xludf.DUMMYFUNCTION("REGEXREPLACE(N3,""(.*)SVL OUT:(.*)"",""$2"")"),"") | P3: ASA | Q3: =T6 | T3: =IFERROR(__xludf.DUMMYFUNCTION("REGEXREPLACE(S3,""(.*)SVL OUT:(.*)"",""$2"")"),"") | W3: 0.020833333 | X3: =OriginalIDP!C5 -> 14.65 | Y3: =OriginalIDP!D5 -> 21 | Z3: =OriginalIDP!E5 -> 6.35 | AA3: 02h00-04h00 | AB3: =AVERAGE(Y9:Y16) -> 19.415 | AC3: 23h00&00h00 | AD3: =VALUE(G5) -> 0 | AE3: =VALUE(G6) -> 0 | AF3: =VALUE(G7) -> 0 | AG3: =VALUE(G8) -> 0 | AH3: =IF(AD3 =0, "Missing", "Logged") -> Missing | AI3: 23h00&00h00 | AJ3: =IF(AD3<>0, AD3, "") | AK3: =IF(AE3<>0, AE3, "") | AL3: =IF(AF3<>0, AF3, "") | AM3: =IF(AG3<>0, AG3, "") | AN3: =COUNTIFS(AM25:AM224, "Sun", AO25:AO224, "0:00") + COUNTIFS(AM25:AM224, "Sun", AO25:AO224, "0:15") + COUNTIFS(AM25:AM224, "Sun", AO25:AO224, "0:30") + COUNTIFS(AM25:AM224, "Sun", AO25:AO224, "0:45") -> 0 | AO3: =COUNTIFS(AM226:AM1170, "Sun", AO226:AO1170, "0:00") + COUNTIFS(AM226:AM1170, "Sun", AO226:AO1170, "0:15") + COUNTIFS(AM226:AM1170, "Sun", AO226:AO1170, "0:30") + COUNTIFS(AM226:AM1170, "Sun", AO226:AO1170, "0:45") -> 0
F4: SAFE | G4: =J7 | J4: =IFERROR(__xludf.DUMMYFUNCTION("REGEXREPLACE(I4,""(.*)SVL IN:(.*)"",""$2"")"),"") | K4: SAFE | L4: =O7 | O4: =IFERROR(__xludf.DUMMYFUNCTION("REGEXREPLACE(N4,""(.*)SVL IN:(.*)"",""$2"")"),"") | P4: SAFE | Q4: =T7 | T4: =IFERROR(__xludf.DUMMYFUNCTION("REGEXREPLACE(S4,""(.*)SVL IN:(.*)"",""$2"")"),"") | W4: 0.03125 | X4: =OriginalIDP!C6 -> 12.93 | Y4: =OriginalIDP!D6 -> 22 | Z4: =OriginalIDP!E6 -> 9.07 | AA4: 04h00-06h00 | AB4: =AVERAGE(Y16:Y24) -> 18.741111 | AC4: 01h00 | AD4: =VALUE(G20) -> 0 | AE4: =VALUE(G21) -> 0 | AF4: =VALUE(G22) -> 0 | AG4: =VALUE(G23) -> 0 | AH4: =IF(AD4 =0, "Missing", "Logged") -> Missing | AI4: 01h00 | AJ4: =IF(AD4<>0, AD4, "") | AK4: =IF(AE4<>0, AE4, "") | AL4: =IF(AF4<>0, AF4, "") | AM4: =IF(AG4<>0, AG4, "") | AN4: =COUNTIFS(AM25:AM224, "Sun", AO25:AO224, "1:00") + COUNTIFS(AM25:AM224, "Sun", AO25:AO224, "1:15") + COUNTIFS(AM25:AM224, "Sun", AO25:AO224, "1:30") + COUNTIFS(AM25:AM224, "Sun", AO25:AO224, "1:45") -> 0 | AO4: =COUNTIFS(AM226:AM1170, "Sun", AO226:AO1170, "1:00") + COUNTIFS(AM226:AM1170, "Sun", AO226:AO1170, "1:15") + COUNTIFS(AM226:AM1170, "Sun", AO226:AO1170, "1:30") + COUNTIFS(AM226:AM1170, "Sun", AO226:AO1170, "1:45") -> 0
F5: SVL Outbound | G5: =J3 | J5: =IFERROR(__xludf.DUMMYFUNCTION("REGEXREPLACE(I5,""(.*)ACK:(.*)"",""$2"")"),"") | K5: SVL Outbound | L5: =O3 | O5: =IFERROR(__xludf.DUMMYFUNCTION("REGEXREPLACE(N5,""(.*)ACK:(.*)"",""$2"")"),"") | P5: SVL Outbound | Q5: =T3 | T5: =IFERROR(__xludf.DUMMYFUNCTION("REGEXREPLACE(S5,""(.*)ACK:(.*)"",""$2"")"),"") | W5: 0.041666667 | X5: =OriginalIDP!C7 -> 16.05 | Y5: =OriginalIDP!D7 -> 23.67 | Z5: =OriginalIDP!E7 -> 7.62 | AA5: 06h00-08h00 | AB5: =AVERAGE(Y24:Y32) -> 27.516667 | AC5: 02h00 | AD5: =VALUE(G35) -> 0 | AE5: =VALUE(G36) -> 0 | AF5: =VALUE(G37) -> 0 | AG5: =VALUE(G38) -> 0 | AH5: =IF(AD5 =0, "Missing", "Logged") -> Missing | AI5: 02h00 | AJ5: =IF(AD5<>0, AD5, "") | AK5: =IF(AE5<>0, AE5, "") | AL5: =IF(AF5<>0, AF5, "") | AM5: =IF(AG5<>0, AG5, "") | AN5: =COUNTIFS(AM25:AM224, "Sun", AO25:AO224, "2:00") + COUNTIFS(AM25:AM224, "Sun", AO25:AO224, "2:15") + COUNTIFS(AM25:AM224, "Sun", AO25:AO224, "2:30") + COUNTIFS(AM25:AM224, "Sun", AO25:AO224, "2:45") -> 0 | AO5: =COUNTIFS(AM226:AM1170, "Sun", AO226:AO1170, "2:00") + COUNTIFS(AM226:AM1170, "Sun", AO226:AO1170, "2:15") + COUNTIFS(AM226:AM1170, "Sun", AO226:AO1170, "2:30") + COUNTIFS(AM226:AM1170, "Sun", AO226:AO1170, "2:45") -> 0
F6: SVL Inbound | G6: =J4 | J6: =IFERROR(__xludf.DUMMYFUNCTION("REGEXREPLACE(I6,""(.*)ASA:(.*)"",""$2"")"),"") | K6: SVL Inbound | L6: =O4 | O6: =IFERROR(__xludf.DUMMYFUNCTION("REGEXREPLACE(N6,""(.*)ASA:(.*)"",""$2"")"),"") | P6: SVL Inbound | Q6: =T4 | T6: =IFERROR(__xludf.DUMMYFUNCTION("REGEXREPLACE(S6,""(.*)ASA:(.*)"",""$2"")"),"") | W6: 0.052083333 | X6: =OriginalIDP!C8 -> 15.88 | Y6: =OriginalIDP!D8 -> 23 | Z6: =OriginalIDP!E8 -> 7.12 | AC6: 03h00 | AD6: =VALUE(G50) -> 0 | AE6: =VALUE(G51) -> 0 | AF6: =VALUE(G52) -> 0 | AG6: =VALUE(G53) -> 0 | AH6: =IF(AD6 =0, "Missing", "Logged") -> Missing | AI6: 03h00 | AJ6: =IF(AD6<>0, AD6, "") | AK6: =IF(AE6<>0, AE6, "") | AL6: =IF(AF6<>0, AF6, "") | AM6: =IF(AG6<>0, AG6, "") | AN6: =COUNTIFS(AM25:AM224, "Sun", AO25:AO224, "3:00") + COUNTIFS(AM25:AM224, "Sun", AO25:AO224, "3:15") + COUNTIFS(AM25:AM224, "Sun", AO25:AO224, "3:30") + COUNTIFS(AM25:AM224, "Sun", AO25:AO224, "3:45") -> 0 | AO6: =COUNTIFS(AM226:AM1170, "Sun", AO226:AO1170, "3:00") + COUNTIFS(AM226:AM1170, "Sun", AO226:AO1170, "3:15") + COUNTIFS(AM226:AM1170, "Sun", AO226:AO1170, "3:30") + COUNTIFS(AM226:AM1170, "Sun", AO226:AO1170, "3:45") -> 0
F7: Trends In: | G7: =J10 | J7: =IFERROR(__xludf.DUMMYFUNCTION("REGEXREPLACE(I7,""(.*)SAFE:(.*)"",""$2"")"),"") | K7: Trends In: | L7: =O10 | O7: =IFERROR(__xludf.DUMMYFUNCTION("REGEXREPLACE(N7,""(.*)SAFE:(.*)"",""$2"")"),"") | P7: Trends In: | Q7: =T10 | T7: =IFERROR(__xludf.DUMMYFUNCTION("REGEXREPLACE(S7,""(.*)SAFE:(.*)"",""$2"")"),"") | W7: 0.0625 | X7: =OriginalIDP!C9 -> 16.36 | Y7: =OriginalIDP!D9 -> 20.33 | Z7: =OriginalIDP!E9 -> 3.97 | AA7: 08h00-10h00 | AB7: =AVERAGE(Y32:Y39) -> 28.0825 | AC7: 04h00 | AD7: =VALUE(G65) -> 0 | AE7: =VALUE(G66) -> 0 | AF7: =VALUE(G67) -> 0 | AG7: =VALUE(G68) -> 0 | AH7: =IF(AD7 =0, "Missing", "Logged") -> Missing | AI7: 04h00 | AJ7: =IF(AD7<>0, AD7, "") | AK7: =IF(AE7<>0, AE7, "") | AL7: =IF(AF7<>0, AF7, "") | AM7: =IF(AG7<>0, AG7, "") | AN7: =COUNTIFS(AM25:AM224, "Sun", AO25:AO224, "4:00") + COUNTIFS(AM25:AM224, "Sun", AO25:AO224, "4:15") + COUNTIFS(AM25:AM224, "Sun", AO25:AO224, "4:30") + COUNTIFS(AM25:AM224, "Sun", AO25:AO224, "4:45") -> 0 | AO7: =COUNTIFS(AM226:AM1170, "Sun", AO226:AO1170, "4:00") + COUNTIFS(AM226:AM1170, "Sun", AO226:AO1170, "4:15") + COUNTIFS(AM226:AM1170, "Sun", AO226:AO1170, "4:30") + COUNTIFS(AM226:AM1170, "Sun", AO226:AO1170, "4:45") -> 0
F8: Trends Out: | G8: =J11 | J8: =IFERROR(__xludf.DUMMYFUNCTION("REGEXREPLACE(I2,""(.*)DELAYS:(.*)"",""$2"")"),"") | K8: Trends Out: | L8: =O11 | O8: =IFERROR(__xludf.DUMMYFUNCTION("REGEXREPLACE(N2,""(.*)DELAYS:(.*)"",""$2"")"),"") | P8: Trends Out: | Q8: =T11 | T8: =IFERROR(__xludf.DUMMYFUNCTION("REGEXREPLACE(S2,""(.*)DELAYS:(.*)"",""$2"")"),"") | W8: 0.072916667 | X8: =OriginalIDP!C10 -> 13.41 | Y8: =OriginalIDP!D10 -> 23 | Z8: =OriginalIDP!E10 -> 9.59 | AA8: 10h00-11h00 | AB8: =Average(Y39:Y43) -> 24.464 | AC8: 05h00 | AD8: =VALUE(G80) -> 0 | AE8: =VALUE(G81) -> 0 | AF8: =VALUE(G82) -> 0 | AG8: =VALUE(G83) -> 0 | AH8: =IF(AD8 =0, "Missing", "Logged") -> Missing | AI8: 05h00 | AJ8: =IF(AD8<>0, AD8, "") | AK8: =IF(AE8<>0, AE8, "") | AL8: =IF(AF8<>0, AF8, "") | AM8: =IF(AG8<>0, AG8, "") | AN8: =COUNTIFS(AM25:AM224, "Sun", AO25:AO224, "5:00") + COUNTIFS(AM25:AM224, "Sun", AO25:AO224, "5:15") + COUNTIFS(AM25:AM224, "Sun", AO25:AO224, "5:30") + COUNTIFS(AM25:AM224, "Sun", AO25:AO224, "5:45") -> 0 | AO8: =COUNTIFS(AM226:AM1170, "Sun", AO226:AO1170, "5:00") + COUNTIFS(AM226:AM1170, "Sun", AO226:AO1170, "5:15") + COUNTIFS(AM226:AM1170, "Sun", AO226:AO1170, "5:30") + COUNTIFS(AM226:AM1170, "Sun", AO226:AO1170, "5:45") -> 0
F9: Delays: | G9: =J13 | J9: =IF(J52=FALSE,"",LEFT(J46,3)) | K9: Delays: | L9: =O13 | O9: =IF(O52=FALSE,"",LEFT(O46,3)) | P9: Delays: | Q9: =T13 | T9: =IF(T52=FALSE,"",LEFT(T46,3)) | W9: 0.09375 | X9: =OriginalIDP!C12 -> 13.38 | Y9: =OriginalIDP!D12 -> 22.66 | Z9: =OriginalIDP!E12 -> 9.28 | AA9: 11h00-12h00 | AB9: =Average(Y43:Y47) -> 31.132 | AC9: 06h00 | AD9: =VALUE(G95) -> 0 | AE9: =VALUE(G96) -> 0 | AF9: =VALUE(G97) -> 0 | AG9: =VALUE(G98) -> 0 | AH9: =IF(AD9 =0, "Missing", "Logged") -> Missing | AI9: 06h00 | AJ9: =IF(AD9<>0, AD9, "") | AK9: =IF(AE9<>0, AE9, "") | AL9: =IF(AF9<>0, AF9, "") | AM9: =IF(AG9<>0, AG9, "") | AN9: =COUNTIFS(AM25:AM224, "Sun", AO25:AO224, "6:00") + COUNTIFS(AM25:AM224, "Sun", AO25:AO224, "6:15") + COUNTIFS(AM25:AM224, "Sun", AO25:AO224, "6:30") + COUNTIFS(AM25:AM224, "Sun", AO25:AO224, "6:45") -> 0 | AO9: =COUNTIFS(AM226:AM1170, "Sun", AO226:AO1170, "6:00") + COUNTIFS(AM226:AM1170, "Sun", AO226:AO1170, "6:15") + COUNTIFS(AM226:AM1170, "Sun", AO226:AO1170, "6:30") + COUNTIFS(AM226:AM1170, "Sun", AO226:AO1170, "6:45") -> 0
J10: =IFERROR(__xludf.DUMMYFUNCTION("REGEXREPLACE(I10,""(.*)Inbound:(.*)"",""$2"")"),"") | O10: =IFERROR(__xludf.DUMMYFUNCTION("REGEXREPLACE(N10,""(.*)Inbound:(.*)"",""$2"")"),"") | T10: =IFERROR(__xludf.DUMMYFUNCTION("REGEXREPLACE(S10,""(.*)Inbound:(.*)"",""$2"")"),"") | W10: 0.10416667 | X10: =OriginalIDP!C13 -> 14.87 | Y10: =OriginalIDP!D13 -> 19 | Z10: =OriginalIDP!E13 -> 4.13 | AA10: 12h00-14h00 | AB10: =AVERAGE(Y47:Y54) -> 32.8325 | AC10: 07h00&08h00 | AD10: =VALUE(L5) -> 0 | AE10: =VALUE(L6) -> 0 | AF10: =VALUE(L7) -> 0 | AG10: =VALUE(L8) -> 0 | AH10: =IF(AD10 =0, "Missing", "Logged") -> Missing | AI10: 07h00&08h00 | AJ10: =IF(AD10<>0, AD10, "") | AK10: =IF(AE10<>0, AE10, "") | AL10: =IF(AF10<>0, AF10, "") | AM10: =IF(AG10<>0, AG10, "") | AN10: =COUNTIFS(AM25:AM224, "Sun", AO25:AO224, "7:00") + COUNTIFS(AM25:AM224, "Sun", AO25:AO224, "7:15") + COUNTIFS(AM25:AM224, "Sun", AO25:AO224, "7:30") + COUNTIFS(AM25:AM224, "Sun", AO25:AO224, "7:45") + COUNTIFS(AM25:AM224, "Sun", AO25:AO224, "8:00") + COUNTIFS(AM25:AM224, "Sun", AO25:AO224, "8:15") + COUNTIFS(AM25:AM224, "Sun", AO25:AO224, "8:30") + COUNTIFS(AM25:AM224, "Sun", AO25:AO224, "8:45") -> 0 | AO10: =COUNTIFS(AM226:AM1170, "Sun", AO226:AO1170, "7:00") + COUNTIFS(AM226:AM1170, "Sun", AO226:AO1170, "7:15") + COUNTIFS(AM226:AM1170, "Sun", AO226:AO1170, "7:30") + COUNTIFS(AM226:AM1170, "Sun", AO226:AO1170, "7:45") + COUNTIFS(AM226:AM1170, "Sun", AO226:AO1170, "8:00") + COUNTIFS(AM226:AM1170, "Sun", AO226:AO1170, "8:15") + COUNTIFS(AM226:AM1170, "Sun", AO226:AO1170, "8:30") + COUNTIFS(AM226:AM1170, "Sun", AO226:AO1170, "8:45") -> 0
F11: Notes | G11: =J15 | J11: =IFERROR(__xludf.DUMMYFUNCTION("REGEXREPLACE(I11,""(.*)Outbound:(.*)"",""$2"")"),"") | K11: Notes | L11: =O15 | O11: =IFERROR(__xludf.DUMMYFUNCTION("REGEXREPLACE(N11,""(.*)Outbound:(.*)"",""$2"")"),"") | P11: Notes | Q11: =T15 | T11: =IFERROR(__xludf.DUMMYFUNCTION("REGEXREPLACE(S11,""(.*)Outbound:(.*)"",""$2"")"),"") | W11: 0.11458333 | X11: =OriginalIDP!C14 -> 15.83 | Y11: =OriginalIDP!D14 -> 18 | Z11: =OriginalIDP!E14 -> 2.17 | AC11: 09h00 | AD11: =VALUE(L20) -> 0 | AE11: =VALUE(L21) -> 0 | AF11: =VALUE(L22) -> 0 | AG11: =VALUE(L23) -> 0 | AH11: =IF(AD11 =0, "Missing", "Logged") -> Missing | AI11: 09h00 | AJ11: =IF(AD11<>0, AD11, "") | AK11: =IF(AE11<>0, AE11, "") | AL11: =IF(AF11<>0, AF11, "") | AM11: =IF(AG11<>0, AG11, "") | AN11: =COUNTIFS(AM25:AM224, "Sun", AO25:AO224, "9:00") + COUNTIFS(AM25:AM224, "Sun", AO25:AO224, "9:15") + COUNTIFS(AM25:AM224, "Sun", AO25:AO224, "9:30") + COUNTIFS(AM25:AM224, "Sun", AO25:AO224, "9:45") -> 0 | AO11: =COUNTIFS(AM226:AM1170, "Sun", AO226:AO1170, "9:00") + COUNTIFS(AM226:AM1170, "Sun", AO226:AO1170, "9:15") + COUNTIFS(AM226:AM1170, "Sun", AO226:AO1170, "9:30") + COUNTIFS(AM226:AM1170, "Sun", AO226:AO1170, "9:45") -> 0
W12: 0.125 | X12: =OriginalIDP!C15 -> 13.36 | Y12: =OriginalIDP!D15 -> 16.67 | Z12: =OriginalIDP!E15 -> 3.31 | AA12: 16h00-18h00 | AB12: =AVERAGE(Y62:Y69) -> 22.70875 | AC12: 10h00 | AD12: =VALUE(L35) -> 0 | AE12: =VALUE(L36) -> 0 | AF12: =VALUE(L37) -> 0 | AG12: =VALUE(L38) -> 0 | AH12: =IF(AD12 =0, "Missing", "Logged") -> Missing | AI12: 10h00 | AJ12: =IF(AD12<>0, AD12, "") | AK12: =IF(AE12<>0, AE12, "") | AL12: =IF(AF12<>0, AF12, "") | AM12: =IF(AG12<>0, AG12, "") | AN12: =COUNTIFS(AM25:AM224, "Sun", AO25:AO224, "10:00") + COUNTIFS(AM25:AM224, "Sun", AO25:AO224, "10:15") + COUNTIFS(AM25:AM224, "Sun", AO25:AO224, "10:30") + COUNTIFS(AM25:AM224, "Sun", AO25:AO224, "10:45") -> 0 | AO12: =COUNTIFS(AM226:AM1170, "Sun", AO226:AO1170, "10:00") + COUNTIFS(AM226:AM1170, "Sun", AO226:AO1170, "10:15") + COUNTIFS(AM226:AM1170, "Sun", AO226:AO1170, "10:30") + COUNTIFS(AM226:AM1170, "Sun", AO226:AO1170, "10:45") -> 0
J13: =Right(I13,100) | O13: =Right(N13,100) | T13: =Right(S13,100) | W13: 0.13541667 | X13: =OriginalIDP!C16 -> 13.46 | Y13: =OriginalIDP!D16 -> 17.33 | Z13: =OriginalIDP!E16 -> 3.87 | AA13: 18h00-20h00 | AB13: =AVERAGE(Y69:Y77) -> 22.591111 | AC13: 11h00 | AD13: =VALUE(L50) -> 0 | AE13: =VALUE(L51) -> 0 | AF13: =VALUE(L52) -> 0 | AG13: =VALUE(L53) -> 0 | AH13: =IF(AD13 =0, "Missing", "Logged") -> Missing | AI13: 11h00 | AJ13: =IF(AD13<>0, AD13, "") | AK13: =IF(AE13<>0, AE13, "") | AL13: =IF(AF13<>0, AF13, "") | AM13: =IF(AG13<>0, AG13, "") | AN13: =COUNTIFS(AM25:AM224, "Sun", AO25:AO224, "11:00") + COUNTIFS(AM25:AM224, "Sun", AO25:AO224, "11:15") + COUNTIFS(AM25:AM224, "Sun", AO25:AO224, "11:30") + COUNTIFS(AM25:AM224, "Sun", AO25:AO224, "11:45") -> 0 | AO13: =COUNTIFS(AM226:AM1170, "Sun", AO226:AO1170, "11:00") + COUNTIFS(AM226:AM1170, "Sun", AO226:AO1170, "11:15") + COUNTIFS(AM226:AM1170, "Sun", AO226:AO1170, "11:30") + COUNTIFS(AM226:AM1170, "Sun", AO226:AO1170, "11:45") -> 0
W14: 0.14583333 | X14: =OriginalIDP!C17 -> 22.56 | Y14: =OriginalIDP!D17 -> 22.33 | Z14: =OriginalIDP!E17 -> -0.23 | AA14: 20h00-22h00 | AB14: =AVERAGE(Y77:Y85) -> 17.184444 | AC14: 12h00 | AD14: =VALUE(L65) -> 0 | AE14: =VALUE(L66) -> 0 | AF14: =VALUE(L67) -> 0 | AG14: =VALUE(L68) -> 0 | AH14: =IF(AD14 =0, "Missing", "Logged") -> Missing | AI14: 12h00 | AJ14: =IF(AD14<>0, AD14, "") | AK14: =IF(AE14<>0, AE14, "") | AL14: =IF(AF14<>0, AF14, "") | AM14: =IF(AG14<>0, AG14, "") | AN14: =COUNTIFS(AM25:AM224, "Sun", AO25:AO224, "12:00") + COUNTIFS(AM25:AM224, "Sun", AO25:AO224, "12:15") + COUNTIFS(AM25:AM224, "Sun", AO25:AO224, "12:30") + COUNTIFS(AM25:AM224, "Sun", AO25:AO224, "12:45") -> 0 | AO14: =COUNTIFS(AM226:AM1170, "Sun", AO226:AO1170, "12:00") + COUNTIFS(AM226:AM1170, "Sun", AO226:AO1170, "12:15") + COUNTIFS(AM226:AM1170, "Sun", AO226:AO1170, "12:30") + COUNTIFS(AM226:AM1170, "Sun", AO226:AO1170, "12:45") -> 0
J15: =Right(I15,150) | O15: =Right(N15,150) | T15: =Right(S15,150) | W15: 0.15625 | X15: =OriginalIDP!C18 -> 22.92 | Y15: =OriginalIDP!D18 -> 19.33 | Z15: =OriginalIDP!E18 -> -3.59 | AA15: 22h00-00h00 | AB15: =AVERAGE(Y85:Y92) -> 16.415 | AC15: 13h00 | AD15: =VALUE(L80) -> 0 | AE15: =VALUE(L81) -> 0 | AF15: =VALUE(L82) -> 0 | AG15: =VALUE(L83) -> 0 | AH15: =IF(AD15 =0, "Missing", "Logged") -> Missing | AI15: 13h00 | AJ15: =IF(AD15<>0, AD15, "") | AK15: =IF(AE15<>0, AE15, "") | AL15: =IF(AF15<>0, AF15, "") | AM15: =IF(AG15<>0, AG15, "") | AN15: =COUNTIFS(AM25:AM224, "Sun", AO25:AO224, "13:00") + COUNTIFS(AM25:AM224, "Sun", AO25:AO224, "13:15") + COUNTIFS(AM25:AM224, "Sun", AO25:AO224, "13:30") + COUNTIFS(AM25:AM224, "Sun", AO25:AO224, "13:45") -> 0 | AO15: =COUNTIFS(AM226:AM1170, "Sun", AO226:AO1170, "13:00") + COUNTIFS(AM226:AM1170, "Sun", AO226:AO1170, "13:15") + COUNTIFS(AM226:AM1170, "Sun", AO226:AO1170, "13:30") + COUNTIFS(AM226:AM1170, "Sun", AO226:AO1170, "13:45") -> 0
F16: Stats Update ~ 01h00 | K16: Stats Update ~ 09h00 | P16: Stats Update ~ 17h00 | W16: 0.16666667 | X16: =OriginalIDP!C19 -> 11.53 | Y16: =OriginalIDP!D19 -> 20 | Z16: =OriginalIDP!E19 -> 8.47 | AC16: 14h00 | AD16: =VALUE(L95) -> 0 | AE16: =VALUE(L96) -> 0 | AF16: =VALUE(L97) -> 0 | AG16: =VALUE(L98) -> 0 | AH16: =IF(AD16 =0, "Missing", "Logged") -> Missing | AI16: 14h00 | AJ16: =IF(AD16<>0, AD16, "") | AK16: =IF(AE16<>0, AE16, "") | AL16: =IF(AF16<>0, AF16, "") | AM16: =IF(AG16<>0, AG16, "") | AN16: =COUNTIFS(AM25:AM224, "Sun", AO25:AO224, "14:00") + COUNTIFS(AM25:AM224, "Sun", AO25:AO224, "14:15") + COUNTIFS(AM25:AM224, "Sun", AO25:AO224, "14:30") + COUNTIFS(AM25:AM224, "Sun", AO25:AO224, "14:45") -> 0 | AO16: =COUNTIFS(AM226:AM1170, "Sun", AO226:AO1170, "14:00") + COUNTIFS(AM226:AM1170, "Sun", AO226:AO1170, "14:15") + COUNTIFS(AM226:AM1170, "Sun", AO226:AO1170, "14:30") + COUNTIFS(AM226:AM1170, "Sun", AO226:AO1170, "14:45") -> 0
F17: ACK | G17: =J20 | J17: =IFERROR(__xludf.DUMMYFUNCTION("REGEXREPLACE(I17,""(.*)ACK:(.*)"",""$2"")"),"") | K17: ACK | L17: =O20 | O17: =IFERROR(__xludf.DUMMYFUNCTION("REGEXREPLACE(N17,""(.*)ACK:(.*)"",""$2"")"),"") | P17: ACK | Q17: =T20 | T17: =IFERROR(__xludf.DUMMYFUNCTION("REGEXREPLACE(S17,""(.*)ACK:(.*)"",""$2"")"),"") | W17: 0.17708333 | X17: =OriginalIDP!C20 -> 14.03 | Y17: =OriginalIDP!D20 -> 17.67 | Z17: =OriginalIDP!E20 -> 3.64 | AC17: 15h00&16h00 | AD17: =VALUE(Q5) -> 0 | AE17: =VALUE(Q6) -> 0 | AF17: =VALUE(Q7) -> 0 | AG17: =VALUE(Q8) -> 0 | AH17: =IF(AD17 =0, "Missing", "Logged") -> Missing | AI17: 15h00&16h00 | AJ17: =IF(AD17<>0, AD17, "") | AK17: =IF(AE17<>0, AE17, "") | AL17: =IF(AF17<>0, AF17, "") | AM17: =IF(AG17<>0, AG17, "") | AN17: =COUNTIFS(AM25:AM224, "Sun", AO25:AO224, "15:00") + COUNTIFS(AM25:AM224, "Sun", AO25:AO224, "15:15") + COUNTIFS(AM25:AM224, "Sun", AO25:AO224, "15:30") + COUNTIFS(AM25:AM224, "Sun", AO25:AO224, "15:45") + COUNTIFS(AM25:AM224, "Sun", AO25:AO224, "16:00") + COUNTIFS(AM25:AM224, "Sun", AO25:AO224, "16:15") + COUNTIFS(AM25:AM224, "Sun", AO25:AO224, "16:30") + COUNTIFS(AM25:AM224, "Sun", AO25:AO224, "16:45") -> 0 | AO17: =COUNTIFS(AM226:AM1170, "Sun", AO226:AO1170, "15:00") + COUNTIFS(AM226:AM1170, "Sun", AO226:AO1170, "15:15") + COUNTIFS(AM226:AM1170, "Sun", AO226:AO1170, "15:30") + COUNTIFS(AM226:AM1170, "Sun", AO226:AO1170, "15:45") + COUNTIFS(AM226:AM1170, "Sun", AO226:AO1170, "16:00") + COUNTIFS(AM226:AM1170, "Sun", AO226:AO1170, "16:15") + COUNTIFS(AM226:AM1170, "Sun", AO226:AO1170, "16:30") + COUNTIFS(AM226:AM1170, "Sun", AO226:AO1170, "16:45") -> 0
F18: ASA | G18: =J21 | J18: =IFERROR(__xludf.DUMMYFUNCTION("REGEXREPLACE(I18,""(.*)SVL OUT:(.*)"",""$2"")"),"") | K18: ASA | L18: =O21 | O18: =IFERROR(__xludf.DUMMYFUNCTION("REGEXREPLACE(N18,""(.*)SVL OUT:(.*)"",""$2"")"),"") | P18: ASA | Q18: =T21 | T18: =IFERROR(__xludf.DUMMYFUNCTION("REGEXREPLACE(S18,""(.*)SVL OUT:(.*)"",""$2"")"),"") | W18: 0.1875 | X18: =OriginalIDP!C21 -> 11.31 | Y18: =OriginalIDP!D21 -> 17.67 | Z18: =OriginalIDP!E21 -> 6.36 | AC18: 17h00 | AD18: =VALUE(Q20) -> 0 | AE18: =VALUE(Q21) -> 0 | AF18: =VALUE(Q22) -> 0 | AG18: =VALUE(Q23) -> 0 | AH18: =IF(AD18 =0, "Missing", "Logged") -> Missing | AI18: 17h00 | AJ18: =IF(AD18<>0, AD18, "") | AK18: =IF(AE18<>0, AE18, "") | AL18: =IF(AF18<>0, AF18, "") | AM18: =IF(AG18<>0, AG18, "") | AN18: =COUNTIFS(AM25:AM224, "Sun", AO25:AO224, "17:00") + COUNTIFS(AM25:AM224, "Sun", AO25:AO224, "17:15") + COUNTIFS(AM25:AM224, "Sun", AO25:AO224, "17:30") + COUNTIFS(AM25:AM224, "Sun", AO25:AO224, "17:45") -> 0 | AO18: =COUNTIFS(AM226:AM1170, "Sun", AO226:AO1170, "17:00") + COUNTIFS(AM226:AM1170, "Sun", AO226:AO1170, "17:15") + COUNTIFS(AM226:AM1170, "Sun", AO226:AO1170, "17:30") + COUNTIFS(AM226:AM1170, "Sun", AO226:AO1170, "17:45") -> 0
F19: SAFE | G19: =J22 | J19: =IFERROR(__xludf.DUMMYFUNCTION("REGEXREPLACE(I19,""(.*)SVL IN:(.*)"",""$2"")"),"") | K19: SAFE | L19: =O22 | O19: =IFERROR(__xludf.DUMMYFUNCTION("REGEXREPLACE(N19,""(.*)SVL IN:(.*)"",""$2"")"),"") | P19: SAFE | Q19: =T22 | T19: =IFERROR(__xludf.DUMMYFUNCTION("REGEXREPLACE(S19,""(.*)SVL IN:(.*)"",""$2"")"),"") | W19: 0.19791667 | X19: =OriginalIDP!C22 -> 12.61 | Y19: =OriginalIDP!D22 -> 16 | Z19: =OriginalIDP!E22 -> 3.39 | AC19: 18h00 | AD19: =VALUE(Q35) -> 0 | AE19: =VALUE(Q36) -> 0 | AF19: =VALUE(Q37) -> 0 | AG19: =VALUE(Q38) -> 0 | AH19: =IF(AD19 =0, "Missing", "Logged") -> Missing | AI19: 18h00 | AJ19: =IF(AD19<>0, AD19, "") | AK19: =IF(AE19<>0, AE19, "") | AL19: =IF(AF19<>0, AF19, "") | AM19: =IF(AG19<>0, AG19, "") | AN19: =COUNTIFS(AM25:AM224, "Sun", AO25:AO224, "18:00") + COUNTIFS(AM25:AM224, "Sun", AO25:AO224, "18:15") + COUNTIFS(AM25:AM224, "Sun", AO25:AO224, "18:30") + COUNTIFS(AM25:AM224, "Sun", AO25:AO224, "18:45") -> 0 | AO19: =COUNTIFS(AM226:AM1170, "Sun", AO226:AO1170, "18:00") + COUNTIFS(AM226:AM1170, "Sun", AO226:AO1170, "18:15") + COUNTIFS(AM226:AM1170, "Sun", AO226:AO1170, "18:30") + COUNTIFS(AM226:AM1170, "Sun", AO226:AO1170, "18:45") -> 0
F20: SVL Outbound | G20: =J18 | J20: =IFERROR(__xludf.DUMMYFUNCTION("REGEXREPLACE(I20,""(.*)ACK:(.*)"",""$2"")"),"") | K20: SVL Outbound | L20: =O18 | O20: =IFERROR(__xludf.DUMMYFUNCTION("REGEXREPLACE(N20,""(.*)ACK:(.*)"",""$2"")"),"") | P20: SVL Outbound | Q20: =T18 | T20: =IFERROR(__xludf.DUMMYFUNCTION("REGEXREPLACE(S20,""(.*)ACK:(.*)"",""$2"")"),"") | W20: 0.20833333 | X20: =OriginalIDP!C23 -> 14.2 | Y20: =OriginalIDP!D23 -> 19 | Z20: =OriginalIDP!E23 -> 4.8 | AC20: 19h00 | AD20: =VALUE(Q50) -> 0 | AE20: =VALUE(Q51) -> 0 | AF20: =VALUE(Q52) -> 0 | AG20: =VALUE(Q53) -> 0 | AH20: =IF(AD20 =0, "Missing", "Logged") -> Missing | AI20: 19h00 | AJ20: =IF(AD20<>0, AD20, "") | AK20: =IF(AE20<>0, AE20, "") | AL20: =IF(AF20<>0, AF20, "") | AM20: =IF(AG20<>0, AG20, "") | AN20: =COUNTIFS(AM25:AM224, "Sun", AO25:AO224, "19:00") + COUNTIFS(AM25:AM224, "Sun", AO25:AO224, "19:15") + COUNTIFS(AM25:AM224, "Sun", AO25:AO224, "19:30") + COUNTIFS(AM25:AM224, "Sun", AO25:AO224, "19:45") -> 0 | AO20: =COUNTIFS(AM226:AM1170, "Sun", AO226:AO1170, "19:00") + COUNTIFS(AM226:AM1170, "Sun", AO226:AO1170, "19:15") + COUNTIFS(AM226:AM1170, "Sun", AO226:AO1170, "19:30") + COUNTIFS(AM226:AM1170, "Sun", AO226:AO1170, "19:45") -> 0
F21: SVL Inbound | G21: =J19 | J21: =IFERROR(__xludf.DUMMYFUNCTION("REGEXREPLACE(I21,""(.*)ASA:(.*)"",""$2"")"),"") | K21: SVL Inbound | L21: =O19 | O21: =IFERROR(__xludf.DUMMYFUNCTION("REGEXREPLACE(N21,""(.*)ASA:(.*)"",""$2"")"),"") | P21: SVL Inbound | Q21: =T19 | T21: =IFERROR(__xludf.DUMMYFUNCTION("REGEXREPLACE(S21,""(.*)ASA:(.*)"",""$2"")"),"") | W21: 0.21875 | X21: =OriginalIDP!C24 -> 13.99 | Y21: =OriginalIDP!D24 -> 18 | Z21: =OriginalIDP!E24 -> 4.01 | AC21: 20h00 | AD21: =VALUE(Q65) -> 0 | AE21: =VALUE(Q66) -> 0 | AF21: =VALUE(Q67) -> 0 | AG21: =VALUE(Q68) -> 0 | AH21: =IF(AD21 =0, "Missing", "Logged") -> Missing | AI21: 20h00 | AJ21: =IF(AD21<>0, AD21, "") | AK21: =IF(AE21<>0, AE21, "") | AL21: =IF(AF21<>0, AF21, "") | AM21: =IF(AG21<>0, AG21, "") | AN21: =COUNTIFS(AM25:AM224, "Sun", AO25:AO224, "20:00") + COUNTIFS(AM25:AM224, "Sun", AO25:AO224, "20:15") + COUNTIFS(AM25:AM224, "Sun", AO25:AO224, "20:30") + COUNTIFS(AM25:AM224, "Sun", AO25:AO224, "20:45") -> 0 | AO21: =COUNTIFS(AM226:AM1170, "Sun", AO226:AO1170, "20:00") + COUNTIFS(AM226:AM1170, "Sun", AO226:AO1170, "20:15") + COUNTIFS(AM226:AM1170, "Sun", AO226:AO1170, "20:30") + COUNTIFS(AM226:AM1170, "Sun", AO226:AO1170, "20:45") -> 0
F22: Trends In: | G22: =J25 | J22: =IFERROR(__xludf.DUMMYFUNCTION("REGEXREPLACE(I22,""(.*)SAFE:(.*)"",""$2"")"),"") | K22: Trends In: | L22: =O25 | O22: =IFERROR(__xludf.DUMMYFUNCTION("REGEXREPLACE(N22,""(.*)SAFE:(.*)"",""$2"")"),"") | P22: Trends In: | Q22: =T25 | T22: =IFERROR(__xludf.DUMMYFUNCTION("REGEXREPLACE(S22,""(.*)SAFE:(.*)"",""$2"")"),"") | W22: 0.22916667 | X22: =OriginalIDP!C25 -> 13.15 | Y22: =OriginalIDP!D25 -> 16.33 | Z22: =OriginalIDP!E25 -> 3.18 | AC22: 21h00 | AD22: =VALUE(Q80) -> 0 | AE22: =VALUE(Q81) -> 0 | AF22: =VALUE(Q82) -> 0 | AG22: =VALUE(Q83) -> 0 | AH22: =IF(AD22 =0, "Missing", "Logged") -> Missing | AI22: 21h00 | AJ22: =IF(AD22<>0, AD22, "") | AK22: =IF(AE22<>0, AE22, "") | AL22: =IF(AF22<>0, AF22, "") | AM22: =IF(AG22<>0, AG22, "") | AN22: =COUNTIFS(AM25:AM224, "Sun", AO25:AO224, "21:00") + COUNTIFS(AM25:AM224, "Sun", AO25:AO224, "21:15") + COUNTIFS(AM25:AM224, "Sun", AO25:AO224, "21:30") + COUNTIFS(AM25:AM224, "Sun", AO25:AO224, "21:45") -> 0 | AO22: =COUNTIFS(AM226:AM1170, "Sun", AO226:AO1170, "21:00") + COUNTIFS(AM226:AM1170, "Sun", AO226:AO1170, "21:15") + COUNTIFS(AM226:AM1170, "Sun", AO226:AO1170, "21:30") + COUNTIFS(AM226:AM1170, "Sun", AO226:AO1170, "21:45") -> 0
F23: Trends Out: | G23: =J26 | J23: =IFERROR(__xludf.DUMMYFUNCTION("REGEXREPLACE(I17,""(.*)DELAYS:(.*)"",""$2"")"),"") | K23: Trends Out: | L23: =O26 | O23: =IFERROR(__xludf.DUMMYFUNCTION("REGEXREPLACE(N17,""(.*)DELAYS:(.*)"",""$2"")"),"") | P23: Trends Out: | Q23: =T26 | T23: =IFERROR(__xludf.DUMMYFUNCTION("REGEXREPLACE(S17,""(.*)DELAYS:(.*)"",""$2"")"),"") | W23: 0.23958333 | X23: =OriginalIDP!C26 -> 14.78 | Y23: =OriginalIDP!D26 -> 18 | Z23: =OriginalIDP!E26 -> 3.22 | AC23: 22h00 | AD23: =VALUE(Q95) -> 0 | AE23: =VALUE(Q96) -> 0 | AF23: =VALUE(Q97) -> 0 | AG23: =VALUE(Q98) -> 0 | AH23: =IF(AD23 =0, "Missing", "Logged") -> Missing | AI23: 22h00 | AJ23: =IF(AD23<>0, AD23, "") | AK23: =IF(AE23<>0, AE23, "") | AL23: =IF(AF23<>0, AF23, "") | AM23: =IF(AG23<>0, AG23, "") | AN23: =COUNTIFS(AM25:AM224, "Sun", AO25:AO224, "22:00") + COUNTIFS(AM25:AM224, "Sun", AO25:AO224, "22:15") + COUNTIFS(AM25:AM224, "Sun", AO25:AO224, "22:30") + COUNTIFS(AM25:AM224, "Sun", AO25:AO224, "22:45") -> 0 | AO23: =COUNTIFS(AM226:AM1170, "Sun", AO226:AO1170, "22:00") + COUNTIFS(AM226:AM1170, "Sun", AO226:AO1170, "22:15") + COUNTIFS(AM226:AM1170, "Sun", AO226:AO1170, "22:30") + COUNTIFS(AM226:AM1170, "Sun", AO226:AO1170, "22:45") -> 0
F24: Delays: | G24: =J28 | J24: =IF(J67=FALSE,"",LEFT(J61,3)) | K24: Delays: | L24: =O28 | O24: =IF(O67=FALSE,"",LEFT(O61,3)) | P24: Delays: | Q24: =T28 | T24: =IF(T67=FALSE,"",LEFT(T61,3)) | W24: 0.25 | X24: =OriginalIDP!C27 -> 14.83 | Y24: =OriginalIDP!D27 -> 26 | Z24: =OriginalIDP!E27 -> 11.17 | AC24: LAW LIFESAFETY UNDER HERE
J25: =IFERROR(__xludf.DUMMYFUNCTION("REGEXREPLACE(I25,""(.*)Inbound:(.*)"",""$2"")"),"") | O25: =IFERROR(__xludf.DUMMYFUNCTION("REGEXREPLACE(N25,""(.*)Inbound:(.*)"",""$2"")"),"") | T25: =IFERROR(__xludf.DUMMYFUNCTION("REGEXREPLACE(S25,""(.*)Inbound:(.*)"",""$2"")"),"") | W25: 0.26041667 | X25: =OriginalIDP!C28 -> 13.81 | Y25: =OriginalIDP!D28 -> 26 | Z25: =OriginalIDP!E28 -> 12.19 | AC25: 1
F26: Notes | G26: =J30 | J26: =IFERROR(__xludf.DUMMYFUNCTION("REGEXREPLACE(I26,""(.*)Outbound:(.*)"",""$2"")"),"") | K26: Notes | L26: =O30 | O26: =IFERROR(__xludf.DUMMYFUNCTION("REGEXREPLACE(N26,""(.*)Outbound:(.*)"",""$2"")"),"") | P26: Notes | Q26: =T30 | T26: =IFERROR(__xludf.DUMMYFUNCTION("REGEXREPLACE(S26,""(.*)Outbound:(.*)"",""$2"")"),"") | W26: 0.27083333 | X26: =OriginalIDP!C29 -> 15.48 | Y26: =OriginalIDP!D29 -> 26 | Z26: =OriginalIDP!E29 -> 10.52 | AC26: 2
W27: 0.28125 | X27: =OriginalIDP!C30 -> 16.59 | Y27: =OriginalIDP!D30 -> 28 | Z27: =OriginalIDP!E30 -> 11.41 | AC27: 3
J28: =Right(I28,100) | O28: =Right(N28,100) | T28: =Right(S28,100) | W28: 0.29166667 | X28: =OriginalIDP!C31 -> 16.86 | Y28: =OriginalIDP!D31 -> 31 | Z28: =OriginalIDP!E31 -> 14.14 | AC28: 4
W29: 0.30208333 | X29: =OriginalIDP!C32 -> 16.78 | Y29: =OriginalIDP!D32 -> 28.33 | Z29: =OriginalIDP!E32 -> 11.55 | AC29: 5
J30: =Right(I30,150) | O30: =Right(N30,150) | T30: =Right(S30,150) | W30: 0.3125 | X30: =OriginalIDP!C33 -> 16.71 | Y30: =OriginalIDP!D33 -> 26.66 | Z30: =OriginalIDP!E33 -> 9.95 | AC30: 6
F31: Stats Update ~ 02h00 | K31: Stats Update ~ 10h00 | P31: Stats Update ~ 18h00 | W31: 0.32291667 | X31: =OriginalIDP!C34 -> 17.19 | Y31: =OriginalIDP!D34 -> 26.33 | Z31: =OriginalIDP!E34 -> 9.14 | AC31: 7
